<mujoco model="empty_floor">
    <compiler angle="radian" />
  <option timestep="0.0005" gravity="0 0 -9.81">
      <flag sensornoise="disable" contact="enable" energy="enable" gravity="enable" />
  </option>
  <asset>
    <texture builtin="gradient" height="256" rgb1=".9 .9 1." rgb2=".2 .3 .4" type="skybox" width="256" />
    <texture file="/home/ubuntu/zhr/robopal/robopal/assets/textures/wood-tiles.png" type="2d" name="texplane" />
    <material name="floorplane" reflectance="0.01" shininess="0.0" specular="0.0" texrepeat="2 2" texture="texplane" texuniform="true" />
  <mesh name="0_base_link" file="/home/ubuntu/zhr/robopal/robopal/assets/models/manipulators/DianaMed/meshes/base_link.STL" />
        <mesh name="0_link1" file="/home/ubuntu/zhr/robopal/robopal/assets/models/manipulators/DianaMed/meshes/link1.STL" />
        <mesh name="0_link2" file="/home/ubuntu/zhr/robopal/robopal/assets/models/manipulators/DianaMed/meshes/link2.STL" />
        <mesh name="0_link3" file="/home/ubuntu/zhr/robopal/robopal/assets/models/manipulators/DianaMed/meshes/link3.STL" />
        <mesh name="0_link4" file="/home/ubuntu/zhr/robopal/robopal/assets/models/manipulators/DianaMed/meshes/link4.STL" />
        <mesh name="0_link5" file="/home/ubuntu/zhr/robopal/robopal/assets/models/manipulators/DianaMed/meshes/link5.STL" />
        <mesh name="0_link6" file="/home/ubuntu/zhr/robopal/robopal/assets/models/manipulators/DianaMed/meshes/link6.STL" />
        <mesh name="0_link7" file="/home/ubuntu/zhr/robopal/robopal/assets/models/manipulators/DianaMed/meshes/link7.STL" />
    <mesh name="0_electric_gripper_base" file="/home/ubuntu/zhr/robopal/robopal/assets/models/grippers/rethink_gripper/meshes/electric_gripper_base.stl" />
        <mesh name="0_standard_narrow" file="/home/ubuntu/zhr/robopal/robopal/assets/models/grippers/rethink_gripper/meshes/standard_narrow.stl" />
        <mesh name="0_half_round_tip" file="/home/ubuntu/zhr/robopal/robopal/assets/models/grippers/rethink_gripper/meshes/half_round_tip.stl" />
        <mesh name="0_connector_plate" file="/home/ubuntu/zhr/robopal/robopal/assets/models/grippers/rethink_gripper/meshes/connector_plate.stl" />
    </asset>
  <asset>
        <mesh file="/home/ubuntu/zhr/robopal/robopal/assets/scenes/../objects/can/can.stl" name="can_mesh" scale="1.0 1.0 1.5" />
        <texture file="/home/ubuntu/zhr/robopal/robopal/assets/textures/can.png" name="tex-can" />
        <material name="coke" reflectance="0.7" texrepeat="5 5" texture="tex-can" texuniform="true" />
  </asset>

  <asset>
        <mesh file="/home/ubuntu/zhr/robopal/robopal/assets/scenes/../objects/can/can.stl" name="cer_mesh" scale="1.0 1.0 1.5" />
        <texture file="/home/ubuntu/zhr/robopal/robopal/assets/textures/ceramic.png" name="tex-cer" />
        <material name="ceramic" reflectance="0.7" texrepeat="5 5" texture="tex-cer" texuniform="true" />
  </asset>

  <asset>
        <mesh file="/home/ubuntu/zhr/robopal/robopal/assets/scenes/../objects/can/can.stl" name="gla_mesh" scale="1.0 1.0 1.5" />
        <texture file="/home/ubuntu/zhr/robopal/robopal/assets/textures/glass.png" name="tex-gla" />
        <material name="glass" reflectance="0.7" texrepeat="5 5" texture="tex-gla" texuniform="true" />
  </asset>


  <worldbody>
    
    <geom condim="3" material="floorplane" name="floor" pos="0 0 0" size="3 3 .125" type="plane" />
    <light diffuse=".8 .8 .8" dir="0 -.15 -1" directional="false" pos="1 1 8.0" specular="0.3 0.3 0.3" castshadow="false" />
    <light diffuse=".8 .8 .8" dir="0 -.15 -1" directional="false" pos="-3. -3. 8.0" specular="0.3 0.3 0.3" castshadow="false" />
    
    <camera mode="fixed" name="frontview" pos="1.6 0 1.45" quat="0.56 0.43 0.43 0.56" />
    
    <camera mode="fixed" name="birdview" pos="-0.2 0 3.0" quat="0.7071 0 0 0.7071" />
    
    <camera mode="fixed" name="agentview" pos="0.5 0 1.35" quat="0.653 0.271 0.271 0.653" />
    
    <camera mode="fixed" name="sideview" pos="-0.05651774593317116 1.2761224129427358 1.4879572214102434" quat="0.009905065491771751 0.006877963156909582 0.5912228352893879 0.806418094001364" />
  
    <body name="table" pos="1 0.3 0.35">
        <geom name="table" type="box" size="0.7 1.0 0.05" rgba="0.9 0.9 0.9 1" />
        <joint type="free" stiffness="0" damping="0.01" frictionloss="0" armature="0" />
        <body name="leg1" pos="0.35 0.7 -0.2">
            <geom name="leg1_geom" type="cylinder" size="0.05 0.15" rgba="0.5 0.5 0.5 1" />
                <inertial pos="0 0 0" quat="1 0 0 0" mass="0.01" diaginertia="0.0008 0.0008 0.0008" />
            
        </body>
        <body name="leg2" pos="-0.35 0.7 -0.2">
            <geom name="leg2_geom" type="cylinder" size="0.05 0.15" rgba="0.5 0.5 0.5 1" />
                <inertial pos="0 0 0" quat="1 0 0 0" mass="0.01" diaginertia="0.0008 0.0008 0.0008" />
            
        </body>
        <body name="leg3" pos="0.35 -0.7 -0.2">
            <geom name="leg3_geom" type="cylinder" size="0.05 0.15" rgba="0.5 0.5 0.5 1" />
                <inertial pos="0 0 0" quat="1 0 0 0" mass="0.01" diaginertia="0.0008 0.0008 0.0008" />
            
        </body>
        <body name="leg4" pos="-0.35 -0.7 -0.2">
            <geom name="leg4_geom" type="cylinder" size="0.05 0.15" rgba="0.5 0.5 0.5 1" />
                <inertial pos="0 0 0" quat="1 0 0 0" mass="0.01" diaginertia="0.0008 0.0008 0.0008" />
            
        </body>
        </body>
         <body pos="0.8 0.3 0.46" name="coke_can">
			<joint name="object0:joint" type="free" damping="0.01" />
			
			
			<geom name="coke_can" pos="0 0 0" size="0.02 0.02 " type="box" solimp="0.998 0.998 0.001" solref="0.001 1" density="100" friction="0.95 0.3 0.1" material="coke" group="1" condim="4" />

			<site name="coke_can" pos="0 0 0" quat="-0.707 0 0.707 0" size="0.02 0.02 0.02" rgba="1 0 0 1" type="sphere" />

			<site rgba="0 0 0 0" size="0.005" pos="0 0 -0.06" name="can_bottom_site" />
			<site rgba="0 0 0 0" size="0.005" pos="0 0 0.04" name="can_top_site" />
			<site rgba="0 0 0 0" size="0.005" pos="0.025 0.025 0" name="can_horizontal_radius_site" />
		</body>

        <body pos="0.8 0.0 0.46" name="ceramic_can">
			<joint name="object1:joint" type="free" damping="0.01" />
			<geom name="ceramic_can" pos="0 0 0" mesh="can_mesh" type="mesh" solimp="0.998 0.998 0.001" solref="0.001 1" density="100" friction="0.95 0.3 0.1" material="ceramic" group="1" condim="4" />
			<geom pos="0 0 0" mesh="can_mesh" type="mesh" material="ceramic" group="1" />
			<site name="ceramic_can" pos="0 0 0" size="0.02 0.02 0.02" rgba="1 0 0 1" type="sphere" />

			<site rgba="0 0 0 0" size="0.005" pos="0 0 -0.06" name="ceramic_bottom_site" />
			<site rgba="0 0 0 0" size="0.005" pos="0 0 0.04" name="ceramic_top_site" />
			<site rgba="0 0 0 0" size="0.005" pos="0.025 0.025 0" name="ceramic_horizontal_radius_site" />
		</body>

        <body pos="0.8 -0.2 0.46" name="glass_can">
			<joint name="object2:joint" type="free" damping="0.01" />
			<geom name="glass_can" pos="0 0 0" mesh="can_mesh" type="mesh" solimp="0.998 0.998 0.001" solref="0.001 1" density="100" friction="0.95 0.3 0.1" material="glass" group="1" condim="4" />
			<geom pos="0 0 0" mesh="can_mesh" type="mesh" material="glass" group="1" />
			<site name="glass_can" pos="0 0 0" size="0.02 0.02 0.02" rgba="1 0 0 1" type="sphere" />
	
			<site rgba="0 0 0 0" size="0.005" pos="0 0 -0.06" name="glass_bottom_site" />
			<site rgba="0 0 0 0" size="0.005" pos="0 0 0.04" name="glass_top_site" />
			<site rgba="0 0 0 0" size="0.005" pos="0.025 0.025 0" name="glass_horizontal_radius_site" />
		</body>
  
  <body name="0_base_link">
            <geom type="mesh" contype="0" conaffinity="0" group="1" pos="0 0 0" rgba="1 1 1 1" mesh="0_base_link" />
            <body name="0_link1" pos="8.7058e-05 -0.00063474 0.2985" quat="-3.67321e-06 1 0 0">
                <inertial pos="4.57641e-06 -0.0439746 0.0236145" quat="0.685631 -0.172505 0.172644 0.685818" mass="2.72698" diaginertia="0.0122186 0.0113371 0.00692616" />
                <joint name="0_j1" pos="0 0 0" axis="0 0 1" limited="true" range="-2.56 2.56" damping="0.1" />
                <geom type="mesh" contype="0" conaffinity="0" group="1" rgba="1 1 1 1" mesh="0_link1" />
                <body name="0_link2" pos="0 0 -0.00092116" quat="0.707105 0.707108 0 0">
                    <inertial pos="8.26088e-06 -0.040728 -0.0363117" quat="0.596612 0.379593 -0.379572 0.596564" mass="3.18168" diaginertia="0.0189254 0.0180721 0.00757505" />
                    <joint name="0_j2" pos="0 0 0" axis="0 0 -1" limited="true" range="-1.57 1.57" damping="0.1" />
                    <geom type="mesh" contype="0" conaffinity="0" group="1" rgba="1 1 1 1" mesh="0_link2" />
                    <body name="0_link3" pos="0 -0.45818 0.0005" quat="0.707105 -0.707108 0 0">
                        <inertial pos="0.0148079 -0.0159925 0.127198" quat="0.874546 -0.136758 -0.0611978 0.461217" mass="3.93616" diaginertia="0.0569273 0.0547312 0.00935482" />
                        <joint name="0_j3" pos="0 0 0" axis="0 0 -1" limited="true" range="-2.56 2.56" damping="0.1" />
                        <geom type="mesh" contype="0" conaffinity="0" group="1" rgba="1 1 1 1" mesh="0_link3" />
                        <body name="0_link4" pos="0.064454 0.0005 -0.00070508" quat="0.707105 0.707108 0 0">
                            <inertial pos="-0.0145884 -0.0117113 -0.0406158" quat="0.00473736 0.651043 0.564294 0.507635" mass="1.58469" diaginertia="0.00499445 0.00482606 0.00267104" />
                            <joint name="0_j4" pos="0 0 0" axis="0 0 1" limited="true" range="0.0 3.05" damping="0.1" />
                            <geom type="mesh" contype="0" conaffinity="0" group="1" rgba="1 1 1 1" mesh="0_link4" />
                            <body name="0_link5" pos="-0.052254 -0.45668 0.0005" quat="0.707105 -0.707108 0 0">
                                <inertial pos="-0.00209922 0.0288297 0.222845" quat="0.985159 0.138333 -0.00891494 0.101222" mass="1.92688" diaginertia="0.0293358 0.0290794 0.00210656" />
                                <joint name="0_j5" pos="0 0 0" axis="0 0 -1" limited="true" range="-3.05 3.05" damping="0.1" />
                                <geom type="mesh" contype="0" conaffinity="0" group="1" rgba="1 1 1 1" mesh="0_link5" />
                                <body name="0_link6" pos="0 -0.005 -1.1713e-05" quat="-2.59734e-06 -2.59735e-06 -0.707108 -0.707105">
                                    <inertial pos="0.038358 -0.00071885 -0.0021112" quat="0.0131349 0.678937 -0.0198942 0.733809" mass="1.7304" diaginertia="0.005268 0.00492614 0.00345065" />
                                    <joint name="0_j6" pos="0 0 0" axis="0 0 1" limited="true" range="-3.14 3.14" damping="0.01" />
                                    <geom type="mesh" contype="0" conaffinity="0" group="1" rgba="1 1 1 1" mesh="0_link6" />
                                    <body name="0_link7" pos="0.076728 -0.1059 0" quat="0.707105 -0.707108 0 0">
                                        <joint name="0_j7" pos="0 0 0" axis="0 0 -1" limited="true" range="-3.14 3.14" damping="0.01" />
                                        <inertial pos="0.00068467 1.5999e-05 0.020834" quat="0.000547318 0.708756 -0.000448023 0.705453" mass="0.16696" diaginertia="0.000143911 8.8902e-05 8.75358e-05" />
                                        <geom type="mesh" contype="0" conaffinity="0" group="1" rgba="1 1 1 1" mesh="0_link7" />
                                        <geom type="mesh" rgba="1 1 1 1" mesh="0_link7" />
                                    <body name="0_gripper_base" pos="0 0 0" quat="0 1 0 0">
            <site name="0_ft_frame" pos="0 0 0" size="0.01 0.01 0.01" rgba="1 0 0 1" type="sphere" group="1" />
            <inertial pos="0 0 0" quat="-0.5 0.5 0.5 0.5" mass="0.0001" diaginertia="3e-08 2e-08 2e-08" />
            <geom type="mesh" contype="0" conaffinity="0" group="1" mesh="0_connector_plate" name="connector_plate" pos="0 0 0.0018" rgba="0.499 0.499 0.499 1" />
            <geom type="mesh" contype="0" conaffinity="0" group="1" mesh="0_electric_gripper_base" name="electric_gripper_base" pos="0 0 0.0194" rgba="0.499 0.499 0.499 1" />
            <geom size="0.029 0.05" quat="0 0 0.707107 0.707107" type="cylinder" group="0" name="gripper_base_col" pos="0.004 0.0 0.04" />
            
            <body name="0_eef" pos="0 0 0.109" quat="0.707105 0 0 -0.707105">
                <site name="0_grip_site" pos="0 0 0" size="0.01 0.01 0.01" rgba="1 0 0 0.5" type="sphere" group="1" />
                <site name="0_ee_x" pos="0.1 0 0" size="0.005 .1" quat="0.707105  0 0.707108 0 " rgba="1 0 0 0" type="cylinder" group="1" />
                <site name="0_ee_y" pos="0 0.1 0" size="0.005 .1" quat="0.707105 0.707108 0 0" rgba="0 1 0 0" type="cylinder" group="1" />
                <site name="0_ee_z" pos="0 0 0.1" size="0.005 .1" quat="1 0 0 0" rgba="0 0 1 0" type="cylinder" group="1" />
                
                
            </body>
            <body name="0_l_finger" pos="0 0.01 0.0444">
                <inertial pos="0 0 0" quat="0 0 0 -1" mass="0.0001" diaginertia="0.001 0.001 0.001" />
                <joint name="0_l_finger_joint" pos="0 0 0" axis="0 1 0" type="slide" limited="true" range="-0.0115 0.020833" damping="100" armature="1.0" frictionloss="1.0" />
                <geom name="l_finger" quat="0 0 0 -1" type="mesh" contype="0" conaffinity="0" group="1" mesh="0_standard_narrow" rgba="0.499 0.499 0.499 1" />
                <geom size="0.005 0.00675 0.0375" pos="0 0.01725 0.04" quat="0 0 0 -1" type="box" group="0" conaffinity="1" contype="0" name="l_finger_g0" friction="0 0 0" />
                <geom size="0.005 0.025 0.0085" pos="-0.005 -0.003 0.0083" quat="0 0 0 -1" type="box" group="0" conaffinity="1" contype="0" name="l_finger_g1" friction="0 0 0" />
                <body name="0_l_finger_tip" pos="0 0.01725 0.075">
                    <inertial pos="0 0 0" quat="0 0 0 1" mass="0.0001" diaginertia="0.001 0.001 0.001" />
                    <geom name="l_fingertip_g0_vis" quat="0 0 0 1" type="mesh" contype="0" conaffinity="0" group="1" mesh="0_half_round_tip" rgba="0.499 0.499 0.499 1" />
                    <geom size="0.004 0.004 0.0185" pos="0 -0.0045 -0.015" quat="0 0 0 -1" type="box" group="0" conaffinity="1" contype="0" name="l_fingertip_g0" friction="0.95 0.3 0.1" />
                    <geom size="0.0035 0.004 0.0165" pos="0 -0.0047 -0.017" type="box" conaffinity="1" contype="0" name="l_fingerpad_g0" friction="0.95 0.3 0.1" />
                </body>
            </body>
            <body name="0_r_finger" pos="0 -0.01 0.0444">
                <inertial pos="0 0 0" mass="0.0001" diaginertia="0.001 0.001 0.001" />
                <joint name="0_r_finger_joint" pos="0 0 0" axis="0 -1 0" type="slide" limited="true" range="-0.020833 0.0115" damping="100" armature="1.0" frictionloss="1.0" />
                <geom name="r_finger" type="mesh" contype="0" conaffinity="0" group="1" mesh="0_standard_narrow" rgba="0.499 0.499 0.499 1" />
                <geom size="0.005 0.00675 0.0375" pos="0 -0.01725 0.04" type="box" group="0" conaffinity="1" contype="0" name="r_finger_g0" friction="0 0 0" />
                <geom size="0.005 0.025 0.0085" pos="0.005 0.003 0.0083" type="box" group="0" conaffinity="1" contype="0" name="r_finger_g1" friction="0 0 0" />
                <body name="0_r_finger_tip" pos="0 -0.01725 0.075">
                    <inertial pos="0 0 0" mass="0.0001" diaginertia="0.001 0.001 0.001" />
                    <geom name="r_fingertip_g0_vis" type="mesh" contype="0" conaffinity="0" group="1" mesh="0_half_round_tip" rgba="0.499 0.499 0.499 1" />
                    <geom size="0.004 0.004 0.0185" pos="0 0.0045 -0.015" type="box" group="0" conaffinity="1" contype="0" name="r_fingertip_g0" friction="0.95 0.3 0.1" />
                    <geom size="0.0035 0.004 0.0165" pos="0 0.0047 -0.017" type="box" conaffinity="1" contype="0" name="r_fingerpad_g0" friction="0.95 0.3 0.1" />
                </body>
            </body>
        </body>
    </body>
                                </body>
                            </body>
                        </body>
                    </body>
                </body>
            </body>
        </body>
    </worldbody>
<actuator><motor name="0_a1" ctrllimited="true" ctrlrange="-100.0 100.0" joint="0_j1" />
        <motor name="0_a2" ctrllimited="true" ctrlrange="-100.0 100.0" joint="0_j2" />
        <motor name="0_a3" ctrllimited="true" ctrlrange="-100.0 100.0" joint="0_j3" />
        <motor name="0_a4" ctrllimited="true" ctrlrange="-100.0 100.0" joint="0_j4" />
        <motor name="0_a5" ctrllimited="true" ctrlrange="-100.0 100.0" joint="0_j5" />
        <motor name="0_a6" ctrllimited="true" ctrlrange="-100.0 100.0" joint="0_j6" />
        <motor name="0_a7" ctrllimited="true" ctrlrange="-100.0 100.0" joint="0_j7" />
    <motor name="0_gripper_l_finger_joint" ctrllimited="true" ctrlrange="-100.0 100.0" joint="0_l_finger_joint" />
    </actuator><default /><contact /><sensor><force name="0_force_ee" site="0_ft_frame" />
        <torque name="0_torque_ee" site="0_ft_frame" />
    </sensor><equality><joint joint1="0_r_finger_joint" joint2="0_l_finger_joint" />
    </equality></mujoco>