<mujoco model="panda hand">
  <compiler angle="radian" autolimits="true"/>

  <option integrator="implicitfast"/>

  <default>
    <default class="panda_hand">
      <material specular="0.5" shininess="0.25"/>
      <joint armature="0.1" damping="1" axis="0 0 1" range="-2.8973 2.8973"/>
      <general dyntype="none" biastype="affine" ctrlrange="-2.8973 2.8973" forcerange="-87 87"/>
      <default class="finger">
        <joint axis="0 1 0" type="slide" range="0 0.04"/>
      </default>

      <default class="visual">
        <geom type="mesh" contype="0" conaffinity="0" group="2"/>
      </default>
      <default class="collision">
        <geom type="mesh" group="4" conaffinity="1" contype="0" condim="4" friction="1 1 1" solimp="1 1 1"/>
        <default class="fingertip_pad_collision_1">
          <geom type="box" size="0.0085 0.004 0.0085" pos="0 0.0055 0.0445"/>
        </default>
        <default class="fingertip_pad_collision_2">
          <geom type="box" size="0.003 0.002 0.003" pos="0.0055 0.002 0.05"/>
        </default>
        <default class="fingertip_pad_collision_3">
          <geom type="box" size="0.003 0.002 0.003" pos="-0.0055 0.002 0.05"/>
        </default>
        <default class="fingertip_pad_collision_4">
          <geom type="box" size="0.003 0.002 0.0035" pos="0.0055 0.002 0.0395"/>
        </default>
        <default class="fingertip_pad_collision_5">
          <geom type="box" size="0.003 0.002 0.0035" pos="-0.0055 0.002 0.0395"/>
        </default>
      </default>
    </default>
  </default>

  <asset>
    <material class="panda_hand" name="white_hand" rgba="1 1 1 1"/>
    <material class="panda_hand" name="off_white_hand" rgba="0.901961 0.921569 0.929412 1"/>
    <material class="panda_hand" name="black_hand" rgba="0.25 0.25 0.25 1"/>

    <!-- Collision meshes -->
    <mesh name="hand_c" file="meshes/hand.stl"/>

    <!-- Visual meshes -->
    <mesh file="meshes/hand_0.obj"/>
    <mesh file="meshes/hand_1.obj"/>
    <mesh file="meshes/hand_2.obj"/>
    <mesh file="meshes/hand_3.obj"/>
    <mesh file="meshes/hand_4.obj"/>
    <mesh file="meshes/finger_0.obj"/>
    <mesh file="meshes/finger_1.obj"/>
  </asset>

  <worldbody>
    <body name="hand" childclass="panda_hand" quat="0 0 0 1">
      <inertial mass="0.73" pos="-0.01 0 0.03" diaginertia="0.001 0.0025 0.0017"/>
      <geom mesh="hand_0" material="off_white_hand" class="visual"/>
      <geom mesh="hand_1" material="black_hand" class="visual"/>
      <geom mesh="hand_2" material="black_hand" class="visual"/>
      <geom mesh="hand_3" material="white_hand" class="visual"/>
      <geom mesh="hand_4" material="off_white_hand" class="visual"/>
      <geom mesh="hand_c" class="collision"/>
      <!-- This site was added for visualization. -->
      <body name="eef" pos="0 0 0.1" quat="0 1 0 0">
          <site name="grip_site" pos="0 0 0" size="0.005" rgba="1 0 0 0.1" type="sphere" group="1"/>
          <site name="ee_x" pos="0.2 0 0" size="0.005 .2"  quat="0.707105  0 0.707108 0 " rgba="1 0 0 0.1" type="cylinder" group="1"/>
          <site name="ee_y" pos="0 0.2 0" size="0.005 .2" quat="0.707105 0.707108 0 0" rgba="0 1 0 0.1" type="cylinder" group="1"/>
          <site name="ee_z" pos="0 0 0.2" size="0.005 .2" quat="1 0 0 0" rgba="0 0 1 0.5" type="cylinder" group="1"/>
          <site name="ee_x_ne" pos="-0.2 0 0" size="0.005 .2"  quat="0.707105  0 0.707108 0 " rgba="1 1 1 0.1" type="cylinder" group="1"/>
          <site name="ee_y_ne" pos="0 -0.2 0" size="0.005 .2" quat="0.707105 0.707108 0 0" rgba="1 1 1 0.1" type="cylinder" group="1"/>
          <site name="ee_z_ne" pos="0 0 -0.2" size="0.005 .2" quat="1 0 0 0" rgba="1 1 1 0.1" type="cylinder" group="1"/>
      </body>
      <body name="left_finger" pos="0 0 0.0584">
        <inertial mass="0.015" pos="0 0 0" diaginertia="2.375e-6 2.375e-6 7.5e-7"/>
        <joint name="finger_joint1" class="finger"/>
        <geom mesh="finger_0" material="off_white_hand" class="visual"/>
        <geom mesh="finger_1" material="black_hand" class="visual"/>
        <geom mesh="finger_0" class="collision"/>
        <geom class="fingertip_pad_collision_1"/>
        <geom class="fingertip_pad_collision_2"/>
        <geom class="fingertip_pad_collision_3"/>
        <geom class="fingertip_pad_collision_4"/>
        <geom class="fingertip_pad_collision_5"/>
      </body>
      <body name="right_finger" pos="0 0 0.0584" quat="0 0 0 1">
        <inertial mass="0.015" pos="0 0 0" diaginertia="2.375e-6 2.375e-6 7.5e-7"/>
        <joint name="finger_joint2" class="finger"/>
        <geom mesh="finger_0" material="off_white_hand" class="visual"/>
        <geom mesh="finger_1" material="black_hand" class="visual"/>
        <geom mesh="finger_0" class="collision"/>
        <geom class="fingertip_pad_collision_1"/>
        <geom class="fingertip_pad_collision_2"/>
        <geom class="fingertip_pad_collision_3"/>
        <geom class="fingertip_pad_collision_4"/>
        <geom class="fingertip_pad_collision_5"/>
      </body>
    </body>
  </worldbody>

  <contact>
    <exclude body1="hand" body2="left_finger"/>
    <exclude body1="hand" body2="right_finger"/>
  </contact>

  <tendon>
    <fixed name="split">
      <joint joint="finger_joint1" coef="0.5"/>
      <joint joint="finger_joint2" coef="0.5"/>
    </fixed>
  </tendon>

  <equality>
    <joint joint1="finger_joint1" joint2="finger_joint2" solimp="0.95 0.99 0.001" solref="0.005 1"/>
  </equality>

  <actuator>
    <!-- Remap original ctrlrange (0, 0.04) to (0, 255): 0.04 * 100 / 255 = 0.01568627451 -->
    <general class="panda_hand" name="actuator8" tendon="split" forcerange="-100 100" ctrlrange="0 255"
      gainprm="0.01568627451 0 0" biasprm="0 -100 -10"/>
  </actuator>
</mujoco>
