<!-- Author: Z.Li, H. Zhou -->
<!-- Date 2023-06-20 -->

<mujoco model="arm_imi_urdf">
  <compiler angle="radian" meshdir="/home/leeezd/tmp/arm_imi/meshes/" autolimits="true"/>
  <default/>
  <asset>
     <mesh name="base_link_body" file="meshes/base_link_body.STL"/>
    <mesh name="link1" file="meshes/imi_link1.STL"/>
    <mesh name="link2" file="meshes/imi_link2.STL"/>
    <mesh name="link3" file="meshes/imi_link3.STL"/>
    <mesh name="link4" file="meshes/imi_link4.STL"/>
    <mesh name="link5" file="meshes/imi_link5.STL"/>
    <mesh name="link6" file="meshes/imi_link6.STL"/>
    <mesh name="link7" file="meshes/imi_link7.STL"/>
  </asset>
  <worldbody>
    <body name="robot_body" pos="0.0 0 0.99">
      <geom type="mesh" contype="0" conaffinity="0" group="1" density="0" rgba="1 1 1 1" mesh="base_link_body"/>
      <body name="left_link1" pos="-0.321 0 0.0" quat="0.707095 0.00 -0.707095 -0.00" gravcomp="0"  >
        <inertial pos="-3.785e-07 3.1699e-08 -0.025784" quat="1 0 0 -7.43287e-06" mass="1.2375" diaginertia="0.0029871 0.0028791 0.0017382"/>
        <joint name="left_j1" pos="0 0 0" axis="0 0 1" limited="true" range="-3.1415 3.1415"/>
        <geom type="mesh" contype="0" conaffinity="0" group="1" density="0" rgba="1 1 1 1" mesh="link1"/>
        <geom type="mesh" rgba="1 0.0 1 1" mesh="link1"/>
        <body name="left_link2" pos="0 0 0" quat="0.707105 0.707108 0 0" gravcomp="0">
          <inertial pos="3.78497e-07 0.025784 -3.16989e-08" quat="0.707107 0.707107 5.25436e-06 -5.25436e-06" mass="1.23747" diaginertia="0.00298709 0.00287905 0.00173824"/>
          <joint name="left_j2" pos="0 0 0" axis="0 0 -1" limited="true" range="-1.57 1.57"/>
          <geom type="mesh" contype="0" conaffinity="0" group="1" density="0" rgba="1 1 1 1" mesh="link2"/>
          <geom type="mesh" rgba="1 1 1 1" mesh="link2"/>
          <body name="left_link3" pos="0 0.13 0" quat="-2.59734e-06 -2.59735e-06 0.707108 0.707105" gravcomp="0">
            <inertial pos="0.2 0 0" quat="0 0.707107 0 0.707107" mass="2.8712" diaginertia="0.057439 0.056005 0.0031559"/>
            <joint name="left_j3" pos="0 0 0" axis="0 0 1"/>
            <geom type="mesh" contype="0" conaffinity="0" group="1" density="0" rgba="1 1 1 1" mesh="link3"/>
            <geom type="mesh" rgba="1 1 1 1" mesh="link3"/>
            <body name="left_link4" pos="0.4 0 0" gravcomp="0">
              <inertial pos="0.1177 4.5948e-07 -2.5419e-08" quat="5.83433e-06 0.707107 5.83433e-06 0.707107" mass="0.94127" diaginertia="0.019139 0.018987 0.00053195"/>
              <joint name="left_j4" pos="0 0 0" axis="0 0 -1" limited="true" range="-2.1415 2.1415"/>
              <geom type="mesh" contype="0" conaffinity="0" group="1" density="0" rgba="1 1 1 1" mesh="link4"/>
              <geom type="mesh" rgba="1 1 1 1" mesh="link4"/>
              <body name="left_link5" pos="0.4 0 0" gravcomp="0">
                <inertial pos="0 0 0" quat="0.707107 0.707107 0 0" mass="0.046406" diaginertia="3.4126e-05 2.3636e-05 1.9116e-05"/>
                <joint name="left_j5" pos="0 0 0" axis="0 0 1" limited="true" range="-0.25 0.25"/>
                <geom type="mesh" contype="0" conaffinity="0" group="1" density="0" rgba="1 1 1 1" mesh="link5"/>
                <geom type="mesh" rgba="1 1 1 1" mesh="link5"/>
                <body name="left_link6" pos="0 0 0" quat="0.5 0.500002 0.499998 -0.5" gravcomp="0">
                  <inertial pos="0 0.0326 0" mass="0.12225" diaginertia="0.00012918 9.9446e-05 6.3838e-05"/>
                  <joint name="left_j6" pos="0 0 0" axis="0 0 -1" limited="true" range="-1.85 1.85"/>
                  <geom type="mesh" contype="0" conaffinity="0" group="1" density="0" rgba="1 1 1 1" mesh="link6"/>
                  <geom type="mesh" rgba="1 1 1 1" mesh="link6"/>
                  <body name="left_link7" pos="0 0.06 0" quat="-2.59734e-06 -2.59735e-06 -0.707108 -0.707105" gravcomp="0">
                    <inertial pos="-0.00065795 -6.8623e-07 0.035542" quat="0.493193 0.492405 -0.507516 0.506681" mass="0.081104" diaginertia="1.46283e-05 1.17757e-05 1.1517e-05"/>
                    <joint name="left_j7" pos="0 0 0" axis="0 0 1"/>
                    <geom type="mesh" contype="0" conaffinity="0" group="1" density="0" rgba="0.89804 0.91765 0.92941 1" mesh="link7"/>
                    <geom type="mesh" rgba="0.89804 0.91765 0.92941 1" mesh="link7"/>
                  </body>
                </body>
              </body>
            </body>
          </body>
        </body>
      </body>
      <body name="right_link1" pos="0.321 0 0.0" quat="0.000 0.707095 0.00 0.707095" gravcomp="0"  >
        <inertial pos="-3.785e-07 3.1699e-08 -0.025784" quat="1 0 0 -7.43287e-06" mass="1.2375" diaginertia="0.0029871 0.0028791 0.0017382"/>
        <joint name="right_j1" pos="0 0 0" axis="0 0 1" limited="true" range="-3.1415 3.1415"/>
        <geom type="mesh" contype="0" conaffinity="0" group="1" density="0" rgba="1 1 1 1" mesh="link1"/>
        <geom type="mesh" rgba="1 1 1 1" mesh="link1"/>
        <body name="right_link2" pos="0 0 0" quat="0.707105 0.707108 0 0" gravcomp="0">
          <inertial pos="3.78497e-07 0.025784 -3.16989e-08" quat="0.707107 0.707107 5.25436e-06 -5.25436e-06" mass="1.23747" diaginertia="0.00298709 0.00287905 0.00173824"/>
          <joint name="right_j2" pos="0 0 0" axis="0 0 -1" limited="true" range="-1.57 1.57"/>
          <geom type="mesh" contype="0" conaffinity="0" group="1" density="0" rgba="1 1 1 1" mesh="link2"/>
          <geom type="mesh" rgba="1 1 1 1" mesh="link2"/>
          <body name="right_link3" pos="0 0.13 0" quat="-2.59734e-06 -2.59735e-06 0.707108 0.707105" gravcomp="0">
            <inertial pos="0.2 0 0" quat="0 0.707107 0 0.707107" mass="2.8712" diaginertia="0.057439 0.056005 0.0031559"/>
            <joint name="right_j3" pos="0 0 0" axis="0 0 1"/>
            <geom type="mesh" contype="0" conaffinity="0" group="1" density="0" rgba="1 1 1 1" mesh="link3"/>
            <geom type="mesh" rgba="1 1 1 1" mesh="link3"/>
            <body name="right_link4" pos="0.4 0 0" gravcomp="0">
              <inertial pos="0.1177 4.5948e-07 -2.5419e-08" quat="5.83433e-06 0.707107 5.83433e-06 0.707107" mass="0.94127" diaginertia="0.019139 0.018987 0.00053195"/>
              <joint name="right_j4" pos="0 0 0" axis="0 0 -1" limited="true" range="-2.1415 2.1415"/>
              <geom type="mesh" contype="0" conaffinity="0" group="1" density="0" rgba="1 1 1 1" mesh="link4"/>
              <geom type="mesh" rgba="1 1 1 1" mesh="link4"/>
              <body name="right_link5" pos="0.4 0 0" gravcomp="0">
                <inertial pos="0 0 0" quat="0.707107 0.707107 0 0" mass="0.046406" diaginertia="3.4126e-05 2.3636e-05 1.9116e-05"/>
                <joint name="right_j5" pos="0 0 0" axis="0 0 1" limited="true" range="-0.25 0.25"/>
                <geom type="mesh" contype="0" conaffinity="0" group="1" density="0" rgba="1 1 1 1" mesh="link5"/>
                <geom type="mesh" rgba="1 1 1 1" mesh="link5"/>
                <body name="right_link6" pos="0 0 0" quat="0.5 0.500002 0.499998 -0.5" gravcomp="0">
                  <inertial pos="0 0.0326 0" mass="0.12225" diaginertia="0.00012918 9.9446e-05 6.3838e-05"/>
                  <joint name="right_j6" pos="0 0 0" axis="0 0 -1" limited="true" range="-1.85 1.85"/>
                  <geom type="mesh" contype="0" conaffinity="0" group="1" density="0" rgba="1 1 1 1" mesh="link6"/>
                  <geom type="mesh" rgba="1 1 1 1" mesh="link6"/>
                  <body name="right_link7" pos="0 0.06 0" quat="-2.59734e-06 -2.59735e-06 -0.707108 -0.707105" gravcomp="0">
                    <inertial pos="-0.00065795 -6.8623e-07 0.035542" quat="0.493193 0.492405 -0.507516 0.506681" mass="0.081104" diaginertia="1.46283e-05 1.17757e-05 1.1517e-05"/>
                    <joint name="right_j7" pos="0 0 0" axis="0 0 1"/>
                    <geom type="mesh" contype="0" conaffinity="0" group="1" density="0" rgba="0.89804 0.91765 0.92941 1" mesh="link7"/>
                    <geom type="mesh" rgba="0.89804 0.91765 0.92941 1" mesh="link7"/>
                  </body>
                </body>
              </body>
            </body>
          </body>
        </body>
      </body>
    </body>
  </worldbody>
  <actuator>
      <motor name="left_m1" ctrllimited="true" ctrlrange="-100.0 100.0"  joint="left_j1"/>
      <motor name="left_m2" ctrllimited="true" ctrlrange="-100.0 100.0"  joint="left_j2"/>
      <motor name="left_m3" ctrllimited="true" ctrlrange="-100.0 100.0"  joint="left_j3"/>
      <motor name="left_m4" ctrllimited="true" ctrlrange="-100.0 100.0"  joint="left_j4"/>
      <motor name="left_m5" ctrllimited="true" ctrlrange="-100.0 100.0"  joint="left_j5"/>
      <motor name="left_m6" ctrllimited="true" ctrlrange="-100.0 100.0"  joint="left_j6"/>
      <motor name="left_m7" ctrllimited="true" ctrlrange="-100.0 100.0"  joint="left_j7"/>
      <motor name="right_m1" ctrllimited="true" ctrlrange="-100.0 100.0"  joint="right_j1"/>
      <motor name="right_m2" ctrllimited="true" ctrlrange="-100.0 100.0"  joint="right_j2"/>
      <motor name="right_m3" ctrllimited="true" ctrlrange="-100.0 100.0"  joint="right_j3"/>
      <motor name="right_m4" ctrllimited="true" ctrlrange="-100.0 100.0"  joint="right_j4"/>
      <motor name="right_m5" ctrllimited="true" ctrlrange="-100.0 100.0"  joint="right_j5"/>
      <motor name="right_m6" ctrllimited="true" ctrlrange="-100.0 100.0"  joint="right_j6"/>
      <motor name="right_m7" ctrllimited="true" ctrlrange="-100.0 100.0"  joint="right_j7"/>
  </actuator>
</mujoco>
