<mujoco>
    <asset>
        <mesh name="robot_stand"  file="meshes/dual_robot_stand.stl" />
        <mesh name="dual_robot_stand_ring" file="meshes/dual_robot_stand_ring.stl" />
        <mesh name="robot_stand2"  file="meshes/dual_robot_stand4.stl" />
        <!-- arm meshes -->
        <mesh name="base_link" file="meshes/base_link.STL"/>
        <mesh name="link1" file="meshes/link1.STL"/>
        <mesh name="link2" file="meshes/link2.STL"/>
        <mesh name="link3" file="meshes/link3.STL"/>
        <mesh name="link4" file="meshes/link4.STL"/>
        <mesh name="link5" file="meshes/link5.STL"/>
        <mesh name="link6" file="meshes/link6.STL"/>
        <mesh name="link7" file="meshes/link7.STL"/>
        <mesh name="mount_cam" file="meshes/cam.STL" />
        <material name="silver" specular="1" shininess="0.5" reflectance="1" emission="0.25" rgba="0.82 0.82 0.82 1"/>
        <material name="grey" specular="1" shininess="0.5" reflectance="1" emission="0.1" rgba="0.5 0.5 0.5 1"/>
        <material name="blue" specular="1" shininess="0.5" reflectance="1" emission="0" rgba="0.678 0.847 0.902 1"/>
        <material name="black" specular="1" shininess="0.5" reflectance="1" emission="0" rgba="0.2 0.2 0.2 1"/>
    </asset>

    <worldbody>
        <body name="my_cylinder">
            <geom size="0.085 0.28" pos="0 0 0.28" type="cylinder" rgba="0.3 0.3 0.3 1" />
            <inertial pos="0.0 0.0 0.0" mass="0.5" diaginertia="0.184 0.1 0.1"/>
            <body name="dual_robot_stand" pos="0.0 0.0 0.56" euler="0 0 0">
                <inertial pos="0 0 0" mass="2.0" diaginertia="0.15 0.15 0.15"/>
                <joint name="base_stand_joint" axis="0 0 1" pos="0 0 0" limited="true" range="-3.0 3.0"/>
                <geom name="robot_stand" type="mesh" mesh="robot_stand2" pos="0 0 0"  conaffinity="0" contype="0"/>
                <body name="mount_cam" pos="0.0 0.0 0.5425" euler="1.570796 0.0 0.0">
                    <inertial pos="0 0 0" quat="1 0 0 0" mass="0" diaginertia="0 0 0"/>
                    <geom type="mesh" contype="0" conaffinity="0" group="1" rgba="0.69804 0.69804 0.69804 1" mesh="mount_cam" />
                    <camera name="mount_cam" mode="fixed" pos="0.0175 0.00 0.00" quat="0 0 1 0" fovy="45"/>
                </body>
                <!-- right arm -->

                <body name="right_base_link" pos="0.15 0 0.46" euler="0.0 0.785398 0.0">
                    <geom type="mesh" rgba="1 1 1 1" mesh="base_link" pos="0 0 0"/>
                    <body name="right_link1" pos="8.7058e-05 -0.00063474 0.2985" quat="-3.67321e-06 1 0 0">
                        <inertial pos="4.57641e-06 -0.0439746 0.0236145" quat="0.685631 -0.172505 0.172644 0.685818" mass="2.72698" diaginertia="0.0122186 0.0113371 0.00692616"/>
                        <joint name="right_j1" pos="0 0 0" axis="0 0 1" limited="true" range="-3.14 3.14" springref="1" armature="1" damping="1"/>
                        <geom type="mesh"  rgba="1 1 1 1" mesh="link1"/>
                        <body name="right_link2" pos="0 0 -0.00092116" quat="0.707105 0.707108 0 0">
                            <inertial pos="8.26088e-06 -0.040728 -0.0363117" quat="0.596612 0.379593 -0.379572 0.596564" mass="3.18168" diaginertia="0.0189254 0.0180721 0.00757505"/>
                            <joint name="right_j2" pos="0 0 0" axis="0 0 -1" limited="true" range="-3.14 3.14" springref="1" armature="1" damping="1"/>
                            <geom type="mesh"  rgba="1 1 1 1" mesh="link2"/>
                            <body name="right_link3" pos="0 -0.45818 0.0005" quat="0.707105 -0.707108 0 0">
                                <inertial pos="0.0148079 -0.0159925 0.127198" quat="0.874546 -0.136758 -0.0611978 0.461217" mass="3.93616" diaginertia="0.0569273 0.0547312 0.00935482"/>
                                <joint name="right_j3" pos="0 0 0" axis="0 0 -1" limited="true" range="-3.14 3.14" springref="1" armature="1" damping="1"/>
                                <geom type="mesh"  rgba="1 1 1 1" mesh="link3"/>
                                <body name="right_link4" pos="0.064454 0.0005 -0.00070508" quat="0.707105 0.707108 0 0">
                                    <inertial pos="-0.0145884 -0.0117113 -0.0406158" quat="0.00473736 0.651043 0.564294 0.507635" mass="1.58469" diaginertia="0.00499445 0.00482606 0.00267104"/>
                                    <joint name="right_j4" pos="0 0 0" axis="0 0 1" limited="true" range="0.0 3.05" damping="0.8"/>
                                    <geom type="mesh"  rgba="1 1 1 1" mesh="link4"/>
                                    <body name="right_link5" pos="-0.052254 -0.45668 0.0005" quat="0.707105 -0.707108 0 0">
                                        <inertial pos="-0.00209922 0.0288297 0.222845" quat="0.985159 0.138333 -0.00891494 0.101222" mass="1.92688" diaginertia="0.0293358 0.0290794 0.00210656"/>
                                        <joint name="right_j5" pos="0 0 0" axis="0 0 -1" limited="true" range="-3.14 3.14" springref="1" armature="1" damping="1"/>
                                        <geom type="mesh"  rgba="1 1 1 1" mesh="link5"/>
                                        <body name="right_link6" pos="0 -0.005 -1.1713e-05" quat="-2.59734e-06 -2.59735e-06 -0.707108 -0.707105">
                                            <inertial pos="0.038358 -0.00071885 -0.0021112" quat="0.0131349 0.678937 -0.0198942 0.733809" mass="1.7304" diaginertia="0.005268 0.00492614 0.00345065"/>
                                            <joint name="right_j6" pos="0 0 0" axis="0 0 1" limited="true" range="-3.14 3.14" damping="0.1"/>
                                            <geom type="mesh"  rgba="1 1 1 1" mesh="link6"/>
                                            <body name="right_link7" pos="0.076728 -0.1059 0" quat="0.707105 -0.707108 0 0">
                                                <inertial pos="0.00068467 1.5999e-05 0.020834" quat="0.000547318 0.708756 -0.000448023 0.705453" mass="0.16696" diaginertia="0.000143911 8.8902e-05 8.75358e-05"/>
                                                <joint name="right_j7" pos="0 0 0" axis="0 0 -1" limited="true" range="-3.14 3.14" damping="0.01"/>
                                                <geom type="mesh"  rgba="1 1 1 1" mesh="link7"/>
                                            </body>
                                        </body>
                                    </body>
                                </body>
                            </body>
                        </body>
                    </body>
                </body>
                <!-- left arm -->
                <body name="left_base_link" pos="-0.15 0 0.46" euler="0.0 -0.785398 3.14">
                    <geom type="mesh" rgba="1 1 1 1" mesh="base_link" pos="0 0 0"/>
                    <body name="left_link1" pos="8.7058e-05 -0.00063474 0.2985" quat="-3.67321e-06 1 0 0">
                        <inertial pos="4.57641e-06 -0.0439746 0.0236145" quat="0.685631 -0.172505 0.172644 0.685818" mass="2.72698" diaginertia="0.0122186 0.0113371 0.00692616"/>
                        <joint name="left_j1" pos="0 0 0" axis="0 0 1" limited="true" range="-3.14 3.14" springref="1" armature="1" damping="1"/>
                        <geom type="mesh"  rgba="1 1 1 1" mesh="link1"/>
                        <body name="left_link2" pos="0 0 -0.00092116" quat="0.707105 0.707108 0 0">
                            <inertial pos="8.26088e-06 -0.040728 -0.0363117" quat="0.596612 0.379593 -0.379572 0.596564" mass="3.18168" diaginertia="0.0189254 0.0180721 0.00757505"/>
                            <joint name="left_j2" pos="0 0 0" axis="0 0 -1" limited="true" range="-3.14 3.14" springref="1" armature="1" damping="1"/>
                            <geom type="mesh"  rgba="1 1 1 1" mesh="link2"/>
                            <body name="left_link3" pos="0 -0.45818 0.0005" quat="0.707105 -0.707108 0 0">
                                <inertial pos="0.0148079 -0.0159925 0.127198" quat="0.874546 -0.136758 -0.0611978 0.461217" mass="3.93616" diaginertia="0.0569273 0.0547312 0.00935482"/>
                                <joint name="left_j3" pos="0 0 0" axis="0 0 -1" limited="true" range="-3.14 3.14" springref="1" armature="1" damping="1"/>
                                <geom type="mesh"  rgba="1 1 1 1" mesh="link3"/>
                                <body name="left_link4" pos="0.064454 0.0005 -0.00070508" quat="0.707105 0.707108 0 0">
                                    <inertial pos="-0.0145884 -0.0117113 -0.0406158" quat="0.00473736 0.651043 0.564294 0.507635" mass="1.58469" diaginertia="0.00499445 0.00482606 0.00267104"/>
                                    <joint name="left_j4" pos="0 0 0" axis="0 0 1" limited="true" range="0.0 3.05" damping="0.8"/>
                                    <geom type="mesh"  rgba="1 1 1 1" mesh="link4"/>
                                    <body name="left_link5" pos="-0.052254 -0.45668 0.0005" quat="0.707105 -0.707108 0 0">
                                        <inertial pos="-0.00209922 0.0288297 0.222845" quat="0.985159 0.138333 -0.00891494 0.101222" mass="1.92688" diaginertia="0.0293358 0.0290794 0.00210656"/>
                                        <joint name="left_j5" pos="0 0 0" axis="0 0 -1" limited="true" range="-3.14 3.14" springref="1" armature="1" damping="1"/>
                                        <geom type="mesh"  rgba="1 1 1 1" mesh="link5"/>
                                        <body name="left_link6" pos="0 -0.005 -1.1713e-05" quat="-2.59734e-06 -2.59735e-06 -0.707108 -0.707105">
                                            <inertial pos="0.038358 -0.00071885 -0.0021112" quat="0.0131349 0.678937 -0.0198942 0.733809" mass="1.7304" diaginertia="0.005268 0.00492614 0.00345065"/>
                                            <joint name="left_j6" pos="0 0 0" axis="0 0 1" limited="true" range="-3.14 3.14" damping="0.1"/>
                                            <geom type="mesh"  rgba="1 1 1 1" mesh="link6"/>
                                            <body name="left_link7" pos="0.076728 -0.1059 0" quat="0.707105 -0.707108 0 0">
                                                <inertial pos="0.00068467 1.5999e-05 0.020834" quat="0.000547318 0.708756 -0.000448023 0.705453" mass="0.16696" diaginertia="0.000143911 8.8902e-05 8.75358e-05"/>
                                                <joint name="left_j7" pos="0 0 0" axis="0 0 -1" limited="true" range="-3.14 3.14" damping="0.01"/>
                                                <geom type="mesh"  rgba="1 1 1 1" mesh="link7"/>
                                            </body>
                                        </body>
                                    </body>
                                </body>
                            </body>
                        </body>
                    </body>
                </body>
            </body>
        </body>
    </worldbody>



    <actuator>
        <motor name="base_stand_joint_motor" joint="base_stand_joint" ctrllimited="true" ctrlrange="-80.0 80.0"/>
        <!-- right arm  -->
        <motor name="right_m1" joint="right_j1" ctrllimited="true" ctrlrange="-80.0 80.0"/>
        <motor name="right_m2" joint="right_j2" ctrllimited="true" ctrlrange="-80.0 80.0"/>
        <motor name="right_m3" joint="right_j3"  ctrllimited="true" ctrlrange="-80.0 80.0"/>
        <motor name="right_m4" joint="right_j4"  ctrllimited="true" ctrlrange="-80.0 80.0"/>
        <motor name="right_m5" joint="right_j5"   ctrllimited="true" ctrlrange="-80.0 80.0"/>
        <motor name="right_m6" joint="right_j6"   ctrllimited="true" ctrlrange="-80.0 80.0"/>
        <motor name="right_m7" joint="right_j7"  ctrllimited="true" ctrlrange="-80.0 80.0"/>

        <!-- left arm  -->
        <motor name="left_m1" joint="left_j1"   ctrllimited="true" ctrlrange="-80.0 80.0"/>
        <motor name="left_m2" joint="left_j2"   ctrllimited="true" ctrlrange="-80.0 80.0"/>
        <motor name="left_m3" joint="left_j3"   ctrllimited="true" ctrlrange="-80.0 80.0"/>
        <motor name="left_m4" joint="left_j4"   ctrllimited="true" ctrlrange="-80.0 80.0"/>
        <motor name="left_m5" joint="left_j5"   ctrllimited="true" ctrlrange="-80.0 80.0"/>
        <motor name="left_m6" joint="left_j6"   ctrllimited="true" ctrlrange="-80.0 80.0"/>
        <motor name="left_m7" joint="left_j7"   ctrllimited="true" ctrlrange="-80.0 80.0"/>
    </actuator>

</mujoco>