<mujoco model="carurdf">
    <asset>
        <mesh name="base_car_link" file="meshes/base_link.STL" />
        <mesh name="wheel_1" file="meshes/wheel_1.STL" />
        <mesh name="wheel_1_1" file="meshes/wheel_1_1.STL" />
        <mesh name="wheel_1_2" file="meshes/wheel_1_2.STL" />
        <mesh name="wheel_1_3" file="meshes/wheel_1_3.STL" />
        <mesh name="wheel_1_4" file="meshes/wheel_1_4.STL" />
        <mesh name="wheel_1_5" file="meshes/wheel_1_5.STL" />
        <mesh name="wheel_1_6" file="meshes/wheel_1_6.STL" />
        <mesh name="wheel_1_7" file="meshes/wheel_1_7.STL" />
        <mesh name="wheel_1_8" file="meshes/wheel_1_8.STL" />
        <mesh name="wheel_1_9" file="meshes/wheel_1_9.STL" />
        <mesh name="wheel_1_10" file="meshes/wheel_1_10.STL" />
        <mesh name="wheel_2" file="meshes/wheel_2.STL" />
        <mesh name="wheel_2_1" file="meshes/wheel_2_1.STL" />
        <mesh name="wheel_2_2" file="meshes/wheel_2_2.STL" />
        <mesh name="wheel_2_3" file="meshes/wheel_2_3.STL" />
        <mesh name="wheel_2_4" file="meshes/wheel_2_4.STL" />
        <mesh name="wheel_2_5" file="meshes/wheel_2_5.STL" />
        <mesh name="wheel_2_6" file="meshes/wheel_2_6.STL" />
        <mesh name="wheel_2_7" file="meshes/wheel_2_7.STL" />
        <mesh name="wheel_2_8" file="meshes/wheel_2_8.STL" />
        <mesh name="wheel_2_9" file="meshes/wheel_2_9.STL" />
        <mesh name="wheel_2_10" file="meshes/wheel_2_10.STL" />
        <mesh name="wheel_3" file="meshes/wheel_3.STL" />
        <mesh name="wheel_3_1" file="meshes/wheel_3_1.STL" />
        <mesh name="wheel_3_2" file="meshes/wheel_3_2.STL" />
        <mesh name="wheel_3_3" file="meshes/wheel_3_3.STL" />
        <mesh name="wheel_3_4" file="meshes/wheel_3_4.STL" />
        <mesh name="wheel_3_5" file="meshes/wheel_3_5.STL" />
        <mesh name="wheel_3_6" file="meshes/wheel_3_6.STL" />
        <mesh name="wheel_3_7" file="meshes/wheel_3_7.STL" />
        <mesh name="wheel_3_8" file="meshes/wheel_3_8.STL" />
        <mesh name="wheel_3_9" file="meshes/wheel_3_9.STL" />
        <mesh name="wheel_3_10" file="meshes/wheel_3_10.STL" />
        <mesh name="wheel_4" file="meshes/wheel_4.STL" />
        <mesh name="wheel_4_1" file="meshes/wheel_4_1.STL" />
        <mesh name="wheel_4_2" file="meshes/wheel_4_2.STL" />
        <mesh name="wheel_4_3" file="meshes/wheel_4_3.STL" />
        <mesh name="wheel_4_4" file="meshes/wheel_4_4.STL" />
        <mesh name="wheel_4_5" file="meshes/wheel_4_5.STL" />
        <mesh name="wheel_4_6" file="meshes/wheel_4_6.STL" />
        <mesh name="wheel_4_7" file="meshes/wheel_4_7.STL" />
        <mesh name="wheel_4_8" file="meshes/wheel_4_8.STL" />
        <mesh name="wheel_4_9" file="meshes/wheel_4_9.STL" />
        <mesh name="wheel_4_10" file="meshes/wheel_4_10.STL" />
    </asset>
    <worldbody>
        <body name="base_car_link" pos="0 0 0.29">
            <inertial diaginertia="1.2869 1.2236 0.9868" mass="70.1294" pos="-0.0036 0 0.0014" quat="0.7605 -0.0133 -0.0061 0.6491" />
            <geom type="mesh" pos="0 0 -0.1" contype="0" conaffinity="0" group="1" rgba="0.792157 0.819608 0.933333 1" mesh="base_car_link" />
            <geom type="mesh" pos="0 0 -0.1" rgba="0.792157 0.819608 0.933333 1" mesh="base_car_link" />
            <joint name="base_x_slide_joint" type="slide" pos="0 0 0" axis="1 0 0" limited="true" range="-1 0.5" damping="15000"/>
            <joint name="base_y_slide_joint" type="slide" pos="0 0 0" axis="0 1 0" limited="true" range="-1 0.5" damping="15000"/>
            <joint name="base_z_hinge_joint" type="hinge" pos="0 0 0" axis="0 0 1" limited="true" range="-0.57 0.57" damping="10000"/>
            <body name="wheel_1" pos="0.320177 -0.247677 -0.1594375" quat="0.92388 0 0 -0.382683">
                <inertial pos="-0.40093 -0.0516986 0.0569862" quat="-0.27013 0.653441 0.270227 0.653469" mass="47.5454" diaginertia="2.73052 1.82823 1.18591" />
                <joint name="wheel_1_x" pos="0 0 0" axis="-1 0 0" />
                <geom type="mesh" contype="0" conaffinity="0" group="1" rgba="0.792157 0.819608 0.933333 1" mesh="wheel_1" />
                <geom type="mesh" rgba="0.792157 0.819608 0.933333 1" mesh="wheel_1" />
                <body name="wheel_1_1" pos="0.0115 -0.0134816 0.104635" quat="0.997948 0.0640252 0 0">
                    <inertial pos="0 0 0" quat="0.707107 0.707107 0 0" mass="0.061182" diaginertia="3.13175e-05 3.13175e-05 1.59889e-05" />
                    <joint name="wheel_1_1_y" pos="0 0 0" axis="0 -1 0" />
                    <geom type="mesh" contype="0" conaffinity="0" group="1" rgba="0.223529 0.223529 0.223529 1" mesh="wheel_1_1" />
                    <geom type="mesh" rgba="0.223529 0.223529 0.223529 1" mesh="wheel_1_1" />
                </body>
                <body name="wheel_1_2" pos="0.0115 0.0458003 0.0838009" quat="0.96889 -0.247491 0 0">
                    <inertial pos="0 0 0" quat="0.707107 0 0 0.707107" mass="0.0660884" diaginertia="4.9494e-05 4.42157e-05 4.42157e-05" />
                    <joint name="wheel_1_2_y" pos="0 0 0" axis="0 -1 0" />
                    <geom type="mesh" contype="0" conaffinity="0" group="1" rgba="0.223529 0.223529 0.223529 1" mesh="wheel_1_2" />
                    <geom type="mesh" rgba="0.223529 0.223529 0.223529 1" mesh="wheel_1_2" />
                </body>
                <body name="wheel_1_3" pos="0.0115 0.0953478 0.0451558" quat="0.84499 -0.534782 0 0">
                    <inertial pos="0 0 0" quat="0.707107 0.707107 0 0" mass="0.061182" diaginertia="3.13175e-05 3.13175e-05 1.59889e-05" />
                    <joint name="wheel_1_3_y" pos="0 0 0" axis="0 -1 0" />
                    <geom type="mesh" contype="0" conaffinity="0" group="1" rgba="0.223529 0.223529 0.223529 1" mesh="wheel_1_3" />
                    <geom type="mesh" rgba="0.223529 0.223529 0.223529 1" mesh="wheel_1_3" />
                </body>
                <body name="wheel_1_4" pos="0.0115 0.0938524 -0.0176627" quat="0.638377 -0.769724 0 0">
                    <inertial pos="0 0 0" quat="0.5 0.5 0.5 0.5" mass="0.0660884" diaginertia="4.9494e-05 4.42157e-05 4.42157e-05" />
                    <joint name="wheel_1_4_y" pos="0 0 0" axis="0 -1 0" />
                    <geom type="mesh" contype="0" conaffinity="0" group="1" rgba="0.223529 0.223529 0.223529 1" mesh="wheel_1_4" />
                    <geom type="mesh" rgba="0.223529 0.223529 0.223529 1" mesh="wheel_1_4" />
                </body>
                <body name="wheel_1_5" pos="0.0115 0.0724098 -0.0767273" quat="0.369275 -0.92932 0 0">
                    <inertial pos="0 0 0" quat="0.707107 0.707107 0 0" mass="0.061182" diaginertia="3.13175e-05 3.13175e-05 1.59889e-05" />
                    <joint name="wheel_1_5_y" pos="0 0 0" axis="0 -1 0" />
                    <geom type="mesh" contype="0" conaffinity="0" group="1" rgba="0.223529 0.223529 0.223529 1" mesh="wheel_1_5" />
                    <geom type="mesh" rgba="0.223529 0.223529 0.223529 1" mesh="wheel_1_5" />
                </body>
                <body name="wheel_1_6" pos="0.0115 0.0122037 -0.094717" quat="0.0640252 -0.997948 0 0">
                    <inertial pos="0 0 0" quat="0.707107 0 0 0.707107" mass="0.0660884" diaginertia="4.9494e-05 4.42157e-05 4.42157e-05" />
                    <joint name="wheel_1_6_y" pos="0 0 0" axis="0 -1 0" />
                    <geom type="mesh" contype="0" conaffinity="0" group="1" rgba="0.223529 0.223529 0.223529 1" mesh="wheel_1_6" />
                    <geom type="mesh" rgba="0.223529 0.223529 0.223529 1" mesh="wheel_1_6" />
                </body>
                <body name="wheel_1_7" pos="0.0115 -0.0505961 -0.0925758" quat="0.247491 0.96889 0 0">
                    <inertial pos="0 0 0" quat="0.707107 0.707107 0 0" mass="0.061182" diaginertia="3.13175e-05 3.13175e-05 1.59889e-05" />
                    <joint name="wheel_1_7_y" pos="0 0 0" axis="0 -1 0" />
                    <geom type="mesh" contype="0" conaffinity="0" group="1" rgba="0.223529 0.223529 0.223529 1" mesh="wheel_1_7" />
                    <geom type="mesh" rgba="0.223529 0.223529 0.223529 1" mesh="wheel_1_7" />
                </body>
                <body name="wheel_1_8" pos="0.0115 -0.0863101 -0.0408756" quat="0.534782 0.84499 0 0">
                    <inertial pos="0 0 0" quat="0.5 0.5 0.5 0.5" mass="0.0660884" diaginertia="4.9494e-05 4.42157e-05 4.42157e-05" />
                    <joint name="wheel_1_8_y" pos="0 0 0" axis="0 -1 0" />
                    <geom type="mesh" contype="0" conaffinity="0" group="1" rgba="0.223529 0.223529 0.223529 1" mesh="wheel_1_8" />
                    <geom type="mesh" rgba="0.223529 0.223529 0.223529 1" mesh="wheel_1_8" />
                </body>
                <body name="wheel_1_9" pos="0.0115 -0.10368 0.0195122" quat="0.769724 0.638377 0 0">
                    <inertial pos="0 0 0" quat="0.707107 0.707107 0 0" mass="0.061182" diaginertia="3.13175e-05 3.13175e-05 1.59889e-05" />
                    <joint name="wheel_1_9_y" pos="0 0 0" axis="0 -1 0" />
                    <geom type="mesh" contype="0" conaffinity="0" group="1" rgba="0.223529 0.223529 0.223529 1" mesh="wheel_1_9" />
                    <geom type="mesh" rgba="0.223529 0.223529 0.223529 1" mesh="wheel_1_9" />
                </body>
                <body name="wheel_1_10" pos="0.0115 -0.0655463 0.0694545" quat="0.92932 0.369275 0 0">
                    <inertial pos="0 0 0" quat="0.707107 0 0 0.707107" mass="0.0660884" diaginertia="4.9494e-05 4.42157e-05 4.42157e-05" />
                    <joint name="wheel_1_10_y" pos="0 0 0" axis="0 -1 0" />
                    <geom type="mesh" contype="0" conaffinity="0" group="1" rgba="0.223529 0.223529 0.223529 1" mesh="wheel_1_10" />
                    <geom type="mesh" rgba="0.223529 0.223529 0.223529 1" mesh="wheel_1_10" />
                </body>
            </body>
            <body name="wheel_2" pos="0.320177 0.247677 -0.1594375" quat="0.92388 0 0 0.382683">
                <inertial pos="-0.401966 0.0506629 0.0569862" quat="0.271061 0.653132 -0.270974 0.653083" mass="47.5454" diaginertia="2.73052 1.82823 1.18591" />
                <joint name="wheel_2_x" pos="0 0 0" axis="-1 0 0" />
                <geom type="mesh" contype="0" conaffinity="0" group="1" rgba="0.792157 0.819608 0.933333 1" mesh="wheel_2" />
                <geom type="mesh" rgba="0.792157 0.819608 0.933333 1" mesh="wheel_2" />
                <body name="wheel_2_1" pos="0.0115 0.0134816 0.104635" quat="0.997948 -0.0640252 0 0">
                    <inertial pos="0 0 0" quat="0.707107 0.707107 0 0" mass="0.061182" diaginertia="3.13175e-05 3.13175e-05 1.59889e-05" />
                    <joint name="wheel_2_1_y" pos="0 0 0" axis="0 1 0" />
                    <geom type="mesh" contype="0" conaffinity="0" group="1" rgba="0.223529 0.223529 0.223529 1" mesh="wheel_2_1" />
                    <geom type="mesh" rgba="0.223529 0.223529 0.223529 1" mesh="wheel_2_1" />
                </body>
                <body name="wheel_2_2" pos="0.0115 0.0655463 0.0694545" quat="0.92932 -0.369275 0 0">
                    <inertial pos="0 0 0" quat="0.5 0.5 0.5 0.5" mass="0.0660884" diaginertia="4.9494e-05 4.42157e-05 4.42157e-05" />
                    <joint name="wheel_2_2_y" pos="0 0 0" axis="0 1 0" />
                    <geom type="mesh" contype="0" conaffinity="0" group="1" rgba="0.223529 0.223529 0.223529 1" mesh="wheel_2_2" />
                    <geom type="mesh" rgba="0.223529 0.223529 0.223529 1" mesh="wheel_2_2" />
                </body>
                <body name="wheel_2_3" pos="0.0115 0.10368 0.0195122" quat="0.769724 -0.638377 0 0">
                    <inertial pos="0 0 0" quat="0.707107 0.707107 0 0" mass="0.061182" diaginertia="3.13175e-05 3.13175e-05 1.59889e-05" />
                    <joint name="wheel_2_3_y" pos="0 0 0" axis="0 1 0" />
                    <geom type="mesh" contype="0" conaffinity="0" group="1" rgba="0.223529 0.223529 0.223529 1" mesh="wheel_2_3" />
                    <geom type="mesh" rgba="0.223529 0.223529 0.223529 1" mesh="wheel_2_3" />
                </body>
                <body name="wheel_2_4" pos="0.0115 0.0863101 -0.0408756" quat="0.534782 -0.84499 0 0">
                    <inertial pos="0 0 0" quat="0.707107 0 0 0.707107" mass="0.0660884" diaginertia="4.9494e-05 4.42157e-05 4.42157e-05" />
                    <joint name="wheel_2_4_y" pos="0 0 0" axis="0 1 0" />
                    <geom type="mesh" contype="0" conaffinity="0" group="1" rgba="0.223529 0.223529 0.223529 1" mesh="wheel_2_4" />
                    <geom type="mesh" rgba="0.223529 0.223529 0.223529 1" mesh="wheel_2_4" />
                </body>
                <body name="wheel_2_5" pos="0.0115 0.0505961 -0.0925758" quat="0.247491 -0.96889 0 0">
                    <inertial pos="0 0 0" quat="0.707107 0.707107 0 0" mass="0.061182" diaginertia="3.13175e-05 3.13175e-05 1.59889e-05" />
                    <joint name="wheel_2_5_y" pos="0 0 0" axis="0 1 0" />
                    <geom type="mesh" contype="0" conaffinity="0" group="1" rgba="0.223529 0.223529 0.223529 1" mesh="wheel_2_5" />
                    <geom type="mesh" rgba="0.223529 0.223529 0.223529 1" mesh="wheel_2_5" />
                </body>
                <body name="wheel_2_6" pos="0.0115 -0.0122037 -0.094717" quat="0.0640252 0.997948 0 0">
                    <inertial pos="0 0 0" quat="0.707107 0 0 0.707107" mass="0.0660884" diaginertia="4.9494e-05 4.42157e-05 4.42157e-05" />
                    <joint name="wheel_2_6_y" pos="0 0 0" axis="0 1 0" />
                    <geom type="mesh" contype="0" conaffinity="0" group="1" rgba="0.223529 0.223529 0.223529 1" mesh="wheel_2_6" />
                    <geom type="mesh" rgba="0.223529 0.223529 0.223529 1" mesh="wheel_2_6" />
                </body>
                <body name="wheel_2_7" pos="0.0115 -0.0724098 -0.0767273" quat="0.369275 0.92932 0 0">
                    <inertial pos="0 0 0" quat="0.707107 0.707107 0 0" mass="0.061182" diaginertia="3.13175e-05 3.13175e-05 1.59889e-05" />
                    <joint name="wheel_2_7_y" pos="0 0 0" axis="0 1 0" />
                    <geom type="mesh" contype="0" conaffinity="0" group="1" rgba="0.223529 0.223529 0.223529 1" mesh="wheel_2_7" />
                    <geom type="mesh" rgba="0.223529 0.223529 0.223529 1" mesh="wheel_2_7" />
                </body>
                <body name="wheel_2_8" pos="0.0115 -0.0938524 -0.0176627" quat="0.638377 0.769724 0 0">
                    <inertial pos="0 0 0" quat="0.707107 0 0 0.707107" mass="0.0660884" diaginertia="4.9494e-05 4.42157e-05 4.42157e-05" />
                    <joint name="wheel_2_8_y" pos="0 0 0" axis="0 1 0" />
                    <geom type="mesh" contype="0" conaffinity="0" group="1" rgba="0.223529 0.223529 0.223529 1" mesh="wheel_2_8" />
                    <geom type="mesh" rgba="0.223529 0.223529 0.223529 1" mesh="wheel_2_8" />
                </body>
                <body name="wheel_2_9" pos="0.0115 -0.0953478 0.0451558" quat="0.84499 0.534782 0 0">
                    <inertial pos="0 0 0" quat="0.707107 0.707107 0 0" mass="0.061182" diaginertia="3.13175e-05 3.13175e-05 1.59889e-05" />
                    <joint name="wheel_2_9_y" pos="0 0 0" axis="0 1 0" />
                    <geom type="mesh" contype="0" conaffinity="0" group="1" rgba="0.223529 0.223529 0.223529 1" mesh="wheel_2_9" />
                    <geom type="mesh" rgba="0.223529 0.223529 0.223529 1" mesh="wheel_2_9" />
                </body>
                <body name="wheel_2_10" pos="0.0115 -0.0458003 0.0838009" quat="0.96889 0.247491 0 0">
                    <inertial pos="0 0 0" quat="0.707107 0 0 0.707107" mass="0.0660884" diaginertia="4.9494e-05 4.42157e-05 4.42157e-05" />
                    <joint name="wheel_2_10_y" pos="0 0 0" axis="0 1 0" />
                    <geom type="mesh" contype="0" conaffinity="0" group="1" rgba="0.223529 0.223529 0.223529 1" mesh="wheel_2_10" />
                    <geom type="mesh" rgba="0.223529 0.223529 0.223529 1" mesh="wheel_2_10" />
                </body>
            </body>
            <body name="wheel_3" pos="-0.320177 0.247677 -0.1594375" quat="0.382683 0 0 0.92388">
                <inertial pos="-0.402135 -0.0508319 0.0569862" quat="-0.270227 0.653469 0.27013 0.653441" mass="47.5454" diaginertia="2.73052 1.82823 1.18591" />
                <joint name="wheel_3_x" pos="0 0 0" axis="-1 0 0" />
                <geom type="mesh" contype="0" conaffinity="0" group="1" rgba="0.792157 0.819608 0.933333 1" mesh="wheel_3" />
                <geom type="mesh" rgba="0.792157 0.819608 0.933333 1" mesh="wheel_3" />
                <body name="wheel_3_1" pos="0.0115 0.00556754 0.0953376" quat="0.999575 -0.0291618 0 0">
                    <inertial pos="0 0 0" quat="0.707107 0 0 0.707107" mass="0.0660884" diaginertia="4.9494e-05 4.42157e-05 4.42157e-05" />
                    <joint name="wheel_3_1_y" pos="0 0 0" axis="0 1 0" />
                    <geom type="mesh" contype="0" conaffinity="0" group="1" rgba="0.223529 0.223529 0.223529 1" mesh="wheel_3_1" />
                    <geom type="mesh" rgba="0.223529 0.223529 0.223529 1" mesh="wheel_3_1" />
                </body>
                <body name="wheel_3_2" pos="0.0115 0.0668818 0.0815909" quat="0.941641 -0.33662 0 0">
                    <inertial pos="0 0 0" quat="0.707107 0.707107 0 0" mass="0.061182" diaginertia="3.13175e-05 3.13175e-05 1.59889e-05" />
                    <joint name="wheel_3_2_y" pos="0 0 0" axis="0 1 0" />
                    <geom type="mesh" contype="0" conaffinity="0" group="1" rgba="0.223529 0.223529 0.223529 1" mesh="wheel_3_2" />
                    <geom type="mesh" rgba="0.223529 0.223529 0.223529 1" mesh="wheel_3_2" />
                </body>
                <body name="wheel_3_3" pos="0.0115 0.0923919 0.0241659" quat="0.791532 -0.611128 0 0">
                    <inertial pos="0 0 0" quat="0.707107 0 0 0.707107" mass="0.0660884" diaginertia="4.9494e-05 4.42157e-05 4.42157e-05" />
                    <joint name="wheel_3_3_y" pos="0 0 0" axis="0 1 0" />
                    <geom type="mesh" contype="0" conaffinity="0" group="1" rgba="0.223529 0.223529 0.223529 1" mesh="wheel_3_3" />
                    <geom type="mesh" rgba="0.223529 0.223529 0.223529 1" mesh="wheel_3_3" />
                </body>
                <body name="wheel_3_4" pos="0.0115 0.0982652 -0.0383953" quat="0.563943 -0.825814 0 0">
                    <inertial pos="0 0 0" quat="0.707107 0.707107 0 0" mass="0.061182" diaginertia="3.13175e-05 3.13175e-05 1.59889e-05" />
                    <joint name="wheel_3_4_y" pos="0 0 0" axis="0 1 0" />
                    <geom type="mesh" contype="0" conaffinity="0" group="1" rgba="0.223529 0.223529 0.223529 1" mesh="wheel_3_4" />
                    <geom type="mesh" rgba="0.223529 0.223529 0.223529 1" mesh="wheel_3_4" />
                </body>
                <body name="wheel_3_5" pos="0.0115 0.0515338 -0.0804022" quat="0.281151 -0.959664 0 0">
                    <inertial pos="0 0 0" quat="0.707107 0 0 0.707107" mass="0.0660884" diaginertia="4.9494e-05 4.42157e-05 4.42157e-05" />
                    <joint name="wheel_3_5_y" pos="0 0 0" axis="0 1 0" />
                    <geom type="mesh" contype="0" conaffinity="0" group="1" rgba="0.223529 0.223529 0.223529 1" mesh="wheel_3_5" />
                    <geom type="mesh" rgba="0.223529 0.223529 0.223529 1" mesh="wheel_3_5" />
                </body>
                <body name="wheel_3_6" pos="0.0115 -0.00615053 -0.105321" quat="0.0291618 0.999575 0 0">
                    <inertial pos="0 0 0" quat="0.707107 0.707107 0 0" mass="0.061182" diaginertia="3.13175e-05 3.13175e-05 1.59889e-05" />
                    <joint name="wheel_3_6_y" pos="0 0 0" axis="0 1 0" />
                    <geom type="mesh" contype="0" conaffinity="0" group="1" rgba="0.223529 0.223529 0.223529 1" mesh="wheel_3_6" />
                    <geom type="mesh" rgba="0.223529 0.223529 0.223529 1" mesh="wheel_3_6" />
                </body>
                <body name="wheel_3_7" pos="0.0115 -0.0605423 -0.0738572" quat="0.33662 0.941641 0 0">
                    <inertial pos="0 0 0" quat="0.707107 0 0 0.707107" mass="0.0660884" diaginertia="4.9494e-05 4.42157e-05 4.42157e-05" />
                    <joint name="wheel_3_7_y" pos="0 0 0" axis="0 1 0" />
                    <geom type="mesh" contype="0" conaffinity="0" group="1" rgba="0.223529 0.223529 0.223529 1" mesh="wheel_3_7" />
                    <geom type="mesh" rgba="0.223529 0.223529 0.223529 1" mesh="wheel_3_7" />
                </body>
                <body name="wheel_3_8" pos="0.0115 -0.102066 -0.0266963" quat="0.611128 0.791532 0 0">
                    <inertial pos="0 0 0" quat="0.707107 0.707107 0 0" mass="0.061182" diaginertia="3.13175e-05 3.13175e-05 1.59889e-05" />
                    <joint name="wheel_3_8_y" pos="0 0 0" axis="0 1 0" />
                    <geom type="mesh" contype="0" conaffinity="0" group="1" rgba="0.223529 0.223529 0.223529 1" mesh="wheel_3_8" />
                    <geom type="mesh" rgba="0.223529 0.223529 0.223529 1" mesh="wheel_3_8" />
                </body>
                <body name="wheel_3_9" pos="0.0115 -0.088951 0.034756" quat="0.825814 0.563943 0 0">
                    <inertial pos="0 0 0" quat="0.707107 0 0 0.707107" mass="0.0660884" diaginertia="4.9494e-05 4.42157e-05 4.42157e-05" />
                    <joint name="wheel_3_9_y" pos="0 0 0" axis="0 1 0" />
                    <geom type="mesh" contype="0" conaffinity="0" group="1" rgba="0.223529 0.223529 0.223529 1" mesh="wheel_3_9" />
                    <geom type="mesh" rgba="0.223529 0.223529 0.223529 1" mesh="wheel_3_9" />
                </body>
                <body name="wheel_3_10" pos="0.0115 -0.05693 0.0888213" quat="0.959664 0.281151 0 0">
                    <inertial pos="0 0 0" quat="0.707107 0.707107 0 0" mass="0.061182" diaginertia="3.13175e-05 3.13175e-05 1.59889e-05" />
                    <joint name="wheel_3_10_y" pos="0 0 0" axis="0 1 0" />
                    <geom type="mesh" contype="0" conaffinity="0" group="1" rgba="0.223529 0.223529 0.223529 1" mesh="wheel_3_10" />
                    <geom type="mesh" rgba="0.223529 0.223529 0.223529 1" mesh="wheel_3_10" />
                </body>
            </body>
            <body name="wheel_4" pos="-0.320177 -0.247677 -0.1594375" quat="0.382683 0 0 -0.92388">
                <inertial pos="-0.401099 0.0518676 0.0569862" quat="0.270974 0.653083 -0.271061 0.653132" mass="47.5454" diaginertia="2.73052 1.82823 1.18591" />
                <joint name="wheel_4_x" pos="0 0 0" axis="-1 0 0" />
                <geom type="mesh" contype="0" conaffinity="0" group="1" rgba="0.792157 0.819608 0.933333 1" mesh="wheel_4" />
                <geom type="mesh" rgba="0.792157 0.819608 0.933333 1" mesh="wheel_4" />
                <body name="wheel_4_1" pos="0.0115 0.0134816 0.104635" quat="0.997948 -0.0640252 0 0">
                    <inertial pos="0 0 0" quat="0.707107 0.707107 0 0" mass="0.061182" diaginertia="3.13175e-05 3.13175e-05 1.59889e-05" />
                    <joint name="wheel_4_1_y" pos="0 0 0" axis="0 1 0" />
                    <geom type="mesh" contype="0" conaffinity="0" group="1" rgba="0.223529 0.223529 0.223529 1" mesh="wheel_4_1" />
                    <geom type="mesh" rgba="0.223529 0.223529 0.223529 1" mesh="wheel_4_1" />
                </body>
                <body name="wheel_4_2" pos="0.0115 0.0655463 0.0694545" quat="0.92932 -0.369275 0 0">
                    <inertial pos="0 0 0" quat="0.5 0.5 0.5 0.5" mass="0.0660884" diaginertia="4.9494e-05 4.42157e-05 4.42157e-05" />
                    <joint name="wheel_4_2_y" pos="0 0 0" axis="0 1 0" />
                    <geom type="mesh" contype="0" conaffinity="0" group="1" rgba="0.223529 0.223529 0.223529 1" mesh="wheel_4_2" />
                    <geom type="mesh" rgba="0.223529 0.223529 0.223529 1" mesh="wheel_4_2" />
                </body>
                <body name="wheel_4_3" pos="0.0115 0.10368 0.0195122" quat="0.769724 -0.638377 0 0">
                    <inertial pos="0 0 0" quat="0.707107 0.707107 0 0" mass="0.061182" diaginertia="3.13175e-05 3.13175e-05 1.59889e-05" />
                    <joint name="wheel_4_3_y" pos="0 0 0" axis="0 1 0" />
                    <geom type="mesh" contype="0" conaffinity="0" group="1" rgba="0.223529 0.223529 0.223529 1" mesh="wheel_4_3" />
                    <geom type="mesh" rgba="0.223529 0.223529 0.223529 1" mesh="wheel_4_3" />
                </body>
                <body name="wheel_4_4" pos="0.0115 0.0863101 -0.0408756" quat="0.534782 -0.84499 0 0">
                    <inertial pos="0 0 0" quat="0.707107 0 0 0.707107" mass="0.0660884" diaginertia="4.9494e-05 4.42157e-05 4.42157e-05" />
                    <joint name="wheel_4_4_y" pos="0 0 0" axis="0 1 0" />
                    <geom type="mesh" contype="0" conaffinity="0" group="1" rgba="0.223529 0.223529 0.223529 1" mesh="wheel_4_4" />
                    <geom type="mesh" rgba="0.223529 0.223529 0.223529 1" mesh="wheel_4_4" />
                </body>
                <body name="wheel_4_5" pos="0.0115 0.0505961 -0.0925758" quat="0.247491 -0.96889 0 0">
                    <inertial pos="0 0 0" quat="0.707107 0.707107 0 0" mass="0.061182" diaginertia="3.13175e-05 3.13175e-05 1.59889e-05" />
                    <joint name="wheel_4_5_y" pos="0 0 0" axis="0 1 0" />
                    <geom type="mesh" contype="0" conaffinity="0" group="1" rgba="0.223529 0.223529 0.223529 1" mesh="wheel_4_5" />
                    <geom type="mesh" rgba="0.223529 0.223529 0.223529 1" mesh="wheel_4_5" />
                </body>
                <body name="wheel_4_6" pos="0.0115 -0.0122037 -0.094717" quat="0.0640252 0.997948 0 0">
                    <inertial pos="0 0 0" quat="0.707107 0 0 0.707107" mass="0.0660884" diaginertia="4.9494e-05 4.42157e-05 4.42157e-05" />
                    <joint name="wheel_4_6_y" pos="0 0 0" axis="0 1 0" />
                    <geom type="mesh" contype="0" conaffinity="0" group="1" rgba="0.223529 0.223529 0.223529 1" mesh="wheel_4_6" />
                    <geom type="mesh" rgba="0.223529 0.223529 0.223529 1" mesh="wheel_4_6" />
                </body>
                <body name="wheel_4_7" pos="0.0115 -0.0724098 -0.0767273" quat="0.369275 0.92932 0 0">
                    <inertial pos="0 0 0" quat="0.707107 0.707107 0 0" mass="0.061182" diaginertia="3.13175e-05 3.13175e-05 1.59889e-05" />
                    <joint name="wheel_4_7_y" pos="0 0 0" axis="0 1 0" />
                    <geom type="mesh" contype="0" conaffinity="0" group="1" rgba="0.223529 0.223529 0.223529 1" mesh="wheel_4_7" />
                    <geom type="mesh" rgba="0.223529 0.223529 0.223529 1" mesh="wheel_4_7" />
                </body>
                <body name="wheel_4_8" pos="0.0115 -0.0938524 -0.0176627" quat="0.638377 0.769724 0 0">
                    <inertial pos="0 0 0" quat="0.707107 0 0 0.707107" mass="0.0660884" diaginertia="4.9494e-05 4.42157e-05 4.42157e-05" />
                    <joint name="wheel_4_8_y" pos="0 0 0" axis="0 1 0" />
                    <geom type="mesh" contype="0" conaffinity="0" group="1" rgba="0.223529 0.223529 0.223529 1" mesh="wheel_4_8" />
                    <geom type="mesh" rgba="0.223529 0.223529 0.223529 1" mesh="wheel_4_8" />
                </body>
                <body name="wheel_4_9" pos="0.0115 -0.0953478 0.0451558" quat="0.84499 0.534782 0 0">
                    <inertial pos="0 0 0" quat="0.707107 0.707107 0 0" mass="0.061182" diaginertia="3.13175e-05 3.13175e-05 1.59889e-05" />
                    <joint name="wheel_4_9_y" pos="0 0 0" axis="0 1 0" />
                    <geom type="mesh" contype="0" conaffinity="0" group="1" rgba="0.223529 0.223529 0.223529 1" mesh="wheel_4_9" />
                    <geom type="mesh" rgba="0.223529 0.223529 0.223529 1" mesh="wheel_4_9" />
                </body>
                <body name="wheel_4_10" pos="0.0115 -0.0458003 0.0838009" quat="0.96889 0.247491 0 0">
                    <inertial pos="0 0 0" quat="0.5 0.5 0.5 0.5" mass="0.0660884" diaginertia="4.9494e-05 4.42157e-05 4.42157e-05" />
                    <joint name="wheel_4_10_y" pos="0 0 0" axis="0 1 0" />
                    <geom type="mesh" contype="0" conaffinity="0" group="1" rgba="0.223529 0.223529 0.223529 1" mesh="wheel_4_10" />
                    <geom type="mesh" rgba="0.223529 0.223529 0.223529 1" mesh="wheel_4_10" />
                </body>
            </body>
        </body>
    </worldbody>


    <actuator>
    </actuator>
</mujoco>
