<mujoco>
    <asset>
        <texture name="aruco" type='2d' file="textures/aruco.png"/>
        <material name="aruco" texture='aruco' texrepeat='1 1' texuniform='false'/>
    </asset>
    <worldbody>
        <body name="aruco" pos="1.0 0 1." euler="0 -1.57 0" >
            <joint name="aruco_x" pos="0 0 0" axis="1 0 0" type="slide" />
            <joint name="aruco_y" pos="0 0 0" axis="0 1 0" type="slide" />
            <joint name="aruco_z" pos="0 0 0" axis="0 0 1" type="slide" />

            <geom name="aruco_box" type="box" size='0.05 0.05 0.001' mass='0.001' material='aruco'/>
        </body>
    </worldbody>
</mujoco>

