<mujoco>
    <worldbody>
        <body pos="{cupboard_x_pos} {cupboard_y_pos} {0.42}" quat="1 0 0 -1" name="cupboard">
            <geom name="cupboard" rgba="0 1 1 1" type="mesh" mesh="cupboard" group="1" contype="0" conaffinity="0" mass="1.0"/>

            <geom type="box" pos="0 0.09 0.19" size="0.12 0.09 0.01" conaffinity="1" condim="3" contype="0" group="4"/>
            <geom type="box" pos="0 0.09 0.10" size="0.12 0.09 0.01" conaffinity="1" condim="3" contype="0" group="4"/>
            <geom type="box" pos="0 0.09 0.01" size="0.12 0.09 0.01" conaffinity="1" condim="3" contype="0" group="4"/>
            <geom type="box" pos="0.115 0.09 0.10" size="0.01 0.09 0.1" conaffinity="1" condim="3" contype="0" group="4"/>
            <geom type="box" pos="-0.115 0.09 0.10" size="0.01 0.09 0.1" conaffinity="1" condim="3" contype="0" group="4"/>
            <geom type="box" pos="0 0.17 0.10" size="0.12 0.01 0.1" conaffinity="1" condim="3" contype="0" group="4"/>

            <body name="drawer_up">
                <joint name="drawer_up:joint" type="slide" armature="0.001" damping="4" frictionloss="2" axis='0 -1 0' limited="true" range="0.0 0.12"/>
                <geom name="drawer_up" rgba="0 1 1 1" type="mesh" mesh="drawer_up" group="1" contype="0" conaffinity="0" mass="1.0"/>

                <geom type="box" pos="0 0.07 0.12" size="0.1 0.08 0.01" conaffinity="1" condim="3" contype="0" group="4"/>
                <geom type="box" pos="0 0.0 0.14" size="0.1 0.01 0.03" conaffinity="1" condim="3" contype="0" group="4"/>
                <geom type="box" pos="0.09 0.07 0.14" size="0.01 0.08 0.03" conaffinity="1" condim="3" contype="0" group="4"/>
                <geom type="box" pos="-0.09 0.07 0.14" size="0.01 0.08 0.03" conaffinity="1" condim="3" contype="0" group="4"/>
                <geom type="cylinder" pos="0 -0.035 0.135" quat="1 0 1 0" size="0.006 0.04" conaffinity="1" condim="3" contype="0" group="4"/>
                <geom type="cylinder" pos="0.035 -0.02 0.135" quat="1 1 0 0" size="0.006 0.016" conaffinity="1" condim="3" contype="0" group="4"/>
                <geom type="cylinder" pos="-0.035 -0.02 0.135" quat="1 1 0 0" size="0.006 0.016" conaffinity="1" condim="3" contype="0" group="4"/>
                <site name="drawer_up" pos="0 -0.035 0.135" size="0.01 0.01 0.01" rgba="0 1 0 1" type="sphere" />
            </body>
            <body name="drawer_down">
                <joint name="drawer_down:joint" type="slide" armature="0.001" damping="4" frictionloss="2" axis='0 -1 0' limited="true" range="0.0 0.12"/>
                <geom name="drawer_down" rgba="0 1 1 1" type="mesh" mesh="drawer_down" group="1" contype="0" conaffinity="0" mass="1.0"/>

                <geom type="box" pos="0 0.07 0.035" size="0.1 0.08 0.01" conaffinity="1" condim="3" contype="0" group="4"/>
                <geom type="box" pos="0 0.0 0.055" size="0.1 0.01 0.03" conaffinity="1" condim="3" contype="0" group="4"/>
                <geom type="box" pos="0.09 0.07 0.055" size="0.01 0.08 0.03" conaffinity="1" condim="3" contype="0" group="4"/>
                <geom type="box" pos="-0.09 0.07 0.05" size="0.01 0.08 0.03" conaffinity="1" condim="3" contype="0" group="4"/>
                <geom type="cylinder" pos="0 -0.035 0.05" quat="1 0 1 0" size="0.006 0.04" conaffinity="1" condim="3" contype="0" group="4"/>
                <geom type="cylinder" pos="0.035 -0.02 0.05" quat="1 1 0 0" size="0.006 0.016" conaffinity="1" condim="3" contype="0" group="4"/>
                <geom type="cylinder" pos="-0.035 -0.02 0.05" quat="1 1 0 0" size="0.006 0.016" conaffinity="1" condim="3" contype="0" group="4"/>

                <site name="drawer_down" pos="0 -0.035 0.05" size="0.01 0.01 0.01" rgba="0 0 1 1" type="sphere" />
            </body>
        </body>
    </worldbody>
</mujoco>
