<mujoco>
    <worldbody>
        <body name="cupboard" pos="0.66 0.0 0.42" quat="1 0 0 -1" >
            <!--  collision  -->
            <geom type="box" pos="0 0.09 0.195" size="0.19 0.09 0.005" conaffinity="1" condim="3" contype="0" group="1" rgba="0.68 0.68 0.68 1"/>
            <geom type="box" pos="0 0.09 0.10" size="0.19 0.09 0.005" conaffinity="1" condim="3" contype="0" group="1" rgba="0.68 0.68 0.68 1"/>
            <geom type="box" pos="0 0.09 0.01" size="0.19 0.09 0.005" conaffinity="1" condim="3" contype="0" group="1" rgba="0.68 0.68 0.68 1"/>
            <geom type="box" pos="0.185 0.09 0.10" size="0.005 0.09 0.1" conaffinity="1" condim="3" contype="0" group="1" rgba="0.68 0.68 0.68 1"/>
            <geom type="box" pos="-0.185 0.09 0.10" size="0.005 0.09 0.1" conaffinity="1" condim="3" contype="0" group="1" rgba="0.68 0.68 0.68 1"/>
            <geom type="box" pos="0 0.175 0.10" size="0.19 0.005 0.1" conaffinity="1" condim="3" contype="0" group="1" rgba="0.68 0.68 0.68 1"/>

            <site name="drawer_goal" pos="0.0 -0.2 0.05" size="0.01 0.01 0.01" rgba="1 0 0 1" type="sphere" />
            <body name="drawer" pos="0.0 0.0 -0.007">
                <joint name="drawer:joint" type="slide" armature="0.001" damping="1" frictionloss="10" axis='0 -1 0' limited="true" range="0.0 0.14"/>
                <!--  collision  -->
                <geom type="box" pos="0 0.08 0.035" size="0.18 0.08 0.005" conaffinity="1" condim="3" contype="1" group="1" friction="0.001 0.09 0.9" rgba="0.68 0.68 0.68 1" />
                <geom type="box" pos="0 -0.005 0.055" size="0.185 0.005 0.03" conaffinity="1" condim="3" contype="1" group="1" friction="0.001 0.09 0.9" rgba="0.68 0.68 0.68 1" />
                <geom type="box" pos="0.175 0.07 0.055" size="0.004 0.08 0.03" conaffinity="1" condim="3" contype="1" group="1" friction="0.001 0.09 0.9" rgba="0.68 0.68 0.68 1" />
                <geom type="box" pos="-0.175 0.07 0.055" size="0.004 0.08 0.03" conaffinity="1" condim="3" contype="1" group="1" friction="0.001 0.09 0.9" rgba="0.68 0.68 0.68 1" />

                <geom type="box" pos="0 -0.04 0.055" size="0.01 0.04 0.005" conaffinity="1" condim="4" contype="1" group="1" rgba="0.2 0.2 0.5 1"/>

                <site name="drawer" pos="0.0 -0.06 0.055" size="0.01 0.01 0.01" rgba="0 0 1 1" type="sphere" />
            </body>
        </body>
    </worldbody>
</mujoco>
