<mujoco model="panda nohand">
  <compiler angle="radian" autolimits="true"/>

  <option integrator="implicitfast" impratio="10"/>

  <default>
    <default class="panda">
      <material specular="0.5" shininess="0.25"/>
      <joint armature="0.1" damping="1" axis="0 0 1" range="-2.8973 2.8973"/>
      <general dyntype="none" biastype="affine" ctrlrange="-2.8973 2.8973" forcerange="-87 87"/>

      <default class="panda/visual">
        <geom type="mesh" contype="0" conaffinity="0" group="2"/>
      </default>
      <default class="panda/collision">
        <geom type="mesh" group="3"/>
      </default>
      <site size="0.001" rgba="0.5 0.5 0.5 0.3" group="4"/>
    </default>
  </default>

  <asset>
    <material class="panda" name="white" rgba="1 1 1 1"/>
    <material class="panda" name="off_white" rgba="0.901961 0.921569 0.929412 1"/>
    <material class="panda" name="dark_grey" rgba="0.25 0.25 0.25 1"/>
    <material class="panda" name="green" rgba="0 1 0 1"/>
    <material class="panda" name="light_blue" rgba="0.039216 0.541176 0.780392 1"/>

    <!-- Collision meshes -->
    <mesh name="link0_c" file="meshes/link0.stl"/>
    <mesh name="link1_c" file="meshes/link1.stl"/>
    <mesh name="link2_c" file="meshes/link2.stl"/>
    <mesh name="link3_c" file="meshes/link3.stl"/>
    <mesh name="link4_c" file="meshes/link4.stl"/>
    <mesh name="link5_c0" file="meshes/link5_collision_0.obj"/>
    <mesh name="link5_c1" file="meshes/link5_collision_1.obj"/>
    <mesh name="link5_c2" file="meshes/link5_collision_2.obj"/>
    <mesh name="link6_c" file="meshes/link6.stl"/>
    <mesh name="link7_c" file="meshes/link7.stl"/>

    <!-- Visual meshes -->
    <mesh file="meshes/link0_0.obj"/>
    <mesh file="meshes/link0_1.obj"/>
    <mesh file="meshes/link0_2.obj"/>
    <mesh file="meshes/link0_3.obj"/>
    <mesh file="meshes/link0_4.obj"/>
    <mesh file="meshes/link0_5.obj"/>
    <mesh file="meshes/link0_7.obj"/>
    <mesh file="meshes/link0_8.obj"/>
    <mesh file="meshes/link0_9.obj"/>
    <mesh file="meshes/link0_10.obj"/>
    <mesh file="meshes/link0_11.obj"/>
    <mesh file="meshes/link1.obj"/>
    <mesh file="meshes/link2.obj"/>
    <mesh file="meshes/link3_0.obj"/>
    <mesh file="meshes/link3_1.obj"/>
    <mesh file="meshes/link3_2.obj"/>
    <mesh file="meshes/link3_3.obj"/>
    <mesh file="meshes/link4_0.obj"/>
    <mesh file="meshes/link4_1.obj"/>
    <mesh file="meshes/link4_2.obj"/>
    <mesh file="meshes/link4_3.obj"/>
    <mesh file="meshes/link5_0.obj"/>
    <mesh file="meshes/link5_1.obj"/>
    <mesh file="meshes/link5_2.obj"/>
    <mesh file="meshes/link6_0.obj"/>
    <mesh file="meshes/link6_1.obj"/>
    <mesh file="meshes/link6_2.obj"/>
    <mesh file="meshes/link6_3.obj"/>
    <mesh file="meshes/link6_4.obj"/>
    <mesh file="meshes/link6_5.obj"/>
    <mesh file="meshes/link6_6.obj"/>
    <mesh file="meshes/link6_7.obj"/>
    <mesh file="meshes/link6_8.obj"/>
    <mesh file="meshes/link6_9.obj"/>
    <mesh file="meshes/link6_10.obj"/>
    <mesh file="meshes/link6_11.obj"/>
    <mesh file="meshes/link6_12.obj"/>
    <mesh file="meshes/link6_13.obj"/>
    <mesh file="meshes/link6_14.obj"/>
    <mesh file="meshes/link6_15.obj"/>
    <mesh file="meshes/link6_16.obj"/>
    <mesh file="meshes/link7_0.obj"/>
    <mesh file="meshes/link7_1.obj"/>
    <mesh file="meshes/link7_2.obj"/>
    <mesh file="meshes/link7_3.obj"/>
    <mesh file="meshes/link7_4.obj"/>
    <mesh file="meshes/link7_5.obj"/>
    <mesh file="meshes/link7_6.obj"/>
    <mesh file="meshes/link7_7.obj"/>
  </asset>

  <worldbody>
    <body name="link0" childclass="panda">
      <inertial mass="0.629769" pos="-0.041018 -0.00014 0.049974"
        fullinertia="0.00315 0.00388 0.004285 8.2904e-7 0.00015 8.2299e-6"/>
      <geom mesh="link0_0" material="off_white" class="panda/visual"/>
      <geom mesh="link0_1" material="dark_grey" class="panda/visual"/>
      <geom mesh="link0_2" material="off_white" class="panda/visual"/>
      <geom mesh="link0_3" material="dark_grey" class="panda/visual"/>
      <geom mesh="link0_4" material="off_white" class="panda/visual"/>
      <geom mesh="link0_5" material="dark_grey" class="panda/visual"/>
      <geom mesh="link0_7" material="white" class="panda/visual"/>
      <geom mesh="link0_8" material="white" class="panda/visual"/>
      <geom mesh="link0_9" material="dark_grey" class="panda/visual"/>
      <geom mesh="link0_10" material="off_white" class="panda/visual"/>
      <geom mesh="link0_11" material="white" class="panda/visual"/>
      <geom mesh="link0_c" class="panda/collision"/>
      <body name="link1" pos="0 0 0.333">
        <inertial mass="4.970684" pos="0.003875 0.002081 -0.04762"
          fullinertia="0.70337 0.70661 0.0091170 -0.00013900 0.0067720 0.019169"/>
        <joint name="joint1" pos="0 0 0" axis="0 0 1" limited="true" range="-2.8973 2.8973" damping="0.1"/>
        <geom material="white" mesh="link1" class="panda/visual"/>
        <geom mesh="link1_c" class="panda/collision"/>
        <body name="link2" quat="1 -1 0 0">
          <inertial mass="0.646926" pos="-0.003141 -0.02872 0.003495"
            fullinertia="0.0079620 2.8110e-2 2.5995e-2 -3.925e-3 1.0254e-2 7.04e-4"/>
          <joint name="joint2" pos="0 0 0" axis="0 0 1" limited="true" range="-1.7628 1.7628" damping="0.1"/>
          <geom material="white" mesh="link2" class="panda/visual"/>
          <geom mesh="link2_c" class="panda/collision"/>
          <body name="link3" pos="0 -0.316 0" quat="1 1 0 0">
            <joint name="joint3" pos="0 0 0" axis="0 0 1" limited="true" range="-2.8973 2.8973" damping="0.1"/>
            <inertial mass="3.228604" pos="2.7518e-2 3.9252e-2 -6.6502e-2"
              fullinertia="3.7242e-2 3.6155e-2 1.083e-2 -4.761e-3 -1.1396e-2 -1.2805e-2"/>
            <geom mesh="link3_0" material="white" class="panda/visual"/>
            <geom mesh="link3_1" material="white" class="panda/visual"/>
            <geom mesh="link3_2" material="white" class="panda/visual"/>
            <geom mesh="link3_3" material="dark_grey" class="panda/visual"/>
            <geom mesh="link3_c" class="panda/collision"/>
            <body name="link4" pos="0.0825 0 0" quat="1 1 0 0">
              <inertial mass="3.587895" pos="-5.317e-2 1.04419e-1 2.7454e-2"
                fullinertia="2.5853e-2 1.9552e-2 2.8323e-2 7.796e-3 -1.332e-3 8.641e-3"/>
              <joint name="joint4" pos="0 0 0" axis="0 0 1" limited="true" range="-3.0718 -0.0698" damping="0.1"/>
              <geom mesh="link4_0" material="white" class="panda/visual"/>
              <geom mesh="link4_1" material="white" class="panda/visual"/>
              <geom mesh="link4_2" material="dark_grey" class="panda/visual"/>
              <geom mesh="link4_3" material="white" class="panda/visual"/>
              <geom mesh="link4_c" class="panda/collision"/>
              <body name="link5" pos="-0.0825 0.384 0" quat="1 -1 0 0">
                <inertial mass="1.225946" pos="-1.1953e-2 4.1065e-2 -3.8437e-2"
                  fullinertia="3.5549e-2 2.9474e-2 8.627e-3 -2.117e-3 -4.037e-3 2.29e-4"/>
                <joint name="joint5" pos="0 0 0" axis="0 0 1" limited="true" range="-2.8973 2.8973" damping="0.1"/>
                <geom mesh="link5_0" material="dark_grey" class="panda/visual"/>
                <geom mesh="link5_1" material="white" class="panda/visual"/>
                <geom mesh="link5_2" material="white" class="panda/visual"/>
                <geom mesh="link5_c0" class="panda/collision"/>
                <geom mesh="link5_c1" class="panda/collision"/>
                <geom mesh="link5_c2" class="panda/collision"/>
                <body name="link6" quat="1 1 0 0">
                  <inertial mass="1.666555" pos="6.0149e-2 -1.4117e-2 -1.0517e-2"
                    fullinertia="1.964e-3 4.354e-3 5.433e-3 1.09e-4 -1.158e-3 3.41e-4"/>
                  <joint name="joint6" pos="0 0 0" axis="0 0 1" limited="true" range="-0.0175 3.7525" damping="0.01"/>
                  <geom mesh="link6_0" material="off_white" class="panda/visual"/>
                  <geom mesh="link6_1" material="white" class="panda/visual"/>
                  <geom mesh="link6_2" material="dark_grey" class="panda/visual"/>
                  <geom mesh="link6_3" material="white" class="panda/visual"/>
                  <geom mesh="link6_4" material="white" class="panda/visual"/>
                  <geom mesh="link6_5" material="white" class="panda/visual"/>
                  <geom mesh="link6_6" material="white" class="panda/visual"/>
                  <geom mesh="link6_7" material="light_blue" class="panda/visual"/>
                  <geom mesh="link6_8" material="light_blue" class="panda/visual"/>
                  <geom mesh="link6_9" material="dark_grey" class="panda/visual"/>
                  <geom mesh="link6_10" material="dark_grey" class="panda/visual"/>
                  <geom mesh="link6_11" material="white" class="panda/visual"/>
                  <geom mesh="link6_12" material="green" class="panda/visual"/>
                  <geom mesh="link6_13" material="white" class="panda/visual"/>
                  <geom mesh="link6_14" material="dark_grey" class="panda/visual"/>
                  <geom mesh="link6_15" material="dark_grey" class="panda/visual"/>
                  <geom mesh="link6_16" material="white" class="panda/visual"/>
                  <geom mesh="link6_c" class="panda/collision"/>
                  <body name="link7" pos="0.088 0 0" quat="1 1 0 0">
                    <inertial mass="7.35522e-01" pos="1.0517e-2 -4.252e-3 6.1597e-2"
                      fullinertia="1.2516e-2 1.0027e-2 4.815e-3 -4.28e-4 -1.196e-3 -7.41e-4"/>
                    <joint name="joint7" pos="0 0 0" axis="0 0 1" limited="true" range="-2.8973 2.8973" damping="0.01"/>
                    <geom mesh="link7_0" material="white" class="panda/visual"/>
                    <geom mesh="link7_1" material="dark_grey" class="panda/visual"/>
                    <geom mesh="link7_2" material="dark_grey" class="panda/visual"/>
                    <geom mesh="link7_3" material="dark_grey" class="panda/visual"/>
                    <geom mesh="link7_4" material="dark_grey" class="panda/visual"/>
                    <geom mesh="link7_5" material="dark_grey" class="panda/visual"/>
                    <geom mesh="link7_6" material="dark_grey" class="panda/visual"/>
                    <geom mesh="link7_7" material="white" class="panda/visual"/>
                    <geom mesh="link7_c" class="panda/collision"/>
                    <body name="attachment" pos="0 0 0.107" quat="0.3826834 0 0 0.9238795">
                      <site name="attachment_site"/>
                    </body>
                  </body>
                </body>
              </body>
            </body>
          </body>
        </body>
      </body>
    </body>
  </worldbody>

  <actuator>
        <!-- Physical limits of the actuator. -->
        <motor ctrllimited="true" ctrlrange="-80.0 80.0" joint="joint1" name="actuator1"/>
        <motor ctrllimited="true" ctrlrange="-80.0 80.0" joint="joint2" name="actuator2"/>
        <motor ctrllimited="true" ctrlrange="-80.0 80.0" joint="joint3" name="actuator3"/>
        <motor ctrllimited="true" ctrlrange="-80.0 80.0" joint="joint4" name="actuator4"/>
        <motor ctrllimited="true" ctrlrange="-80.0 80.0" joint="joint5" name="actuator5"/>
        <motor ctrllimited="true" ctrlrange="-12.0 12.0" joint="joint6" name="actuator6"/>
        <motor ctrllimited="true" ctrlrange="-12.0 12.0" joint="joint7" name="actuator7"/>
    </actuator>

  <keyframe>
    <key name="home" qpos="0 0 0 -1.57079 0 1.57079 -0.7853" ctrl="0 0 0 -1.57079 0 1.57079 -0.7853"/>
  </keyframe>
</mujoco>
