<mujoco model="DianaMed">
    <compiler angle="radian"/>
    <visual>
            <headlight ambient="0.5 0.5 0.5"/>
    </visual>
    <option timestep="0.0005" integrator="implicitfast" gravity="0 0 -9.81">
        <flag contact="enable" energy="enable" gravity="enable"/>
    </option>
    <asset>
        <mesh name="base_link" file="meshes/base_link.STL"/>
        <mesh name="link1" file="meshes/link1.STL"/>
        <mesh name="link2" file="meshes/link2.STL"/>
        <mesh name="link3" file="meshes/link3.STL"/>
        <mesh name="link4" file="meshes/link4.STL"/>
        <mesh name="link5" file="meshes/link5.STL"/>
        <mesh name="link6" file="meshes/link6.STL"/>
        <mesh name="link7" file="meshes/link7.STL"/>
    </asset>
    <worldbody>
        <body name="base_link">
            <geom type="mesh" contype="0" conaffinity="0" group="1" pos="0 0 0" rgba="1 1 1 1" mesh="base_link"/>
            <body name="link1" pos="8.7058e-05 -0.00063474 0.2985" quat="-3.67321e-06 1 0 0">
                <inertial pos="4.57641e-06 -0.0439746 0.0236145" quat="0.685631 -0.172505 0.172644 0.685818" mass="2.72698" diaginertia="0.0122186 0.0113371 0.00692616"/>
                <joint name="j1" pos="0 0 0" axis="0 0 1" limited="true" range="-2.56 2.56" damping="0.05"/>
                <geom type="mesh" contype="0" conaffinity="0" group="1" rgba="1 1 1 1" mesh="link1"/>
<!--                <geom name="link1_collision" type="mesh" rgba="1 1 1 1" mesh="link1"/>-->
                <body name="link2" pos="0 0 -0.00092116" quat="0.707105 0.707108 0 0">
                    <inertial pos="8.26088e-06 -0.040728 -0.0363117" quat="0.596612 0.379593 -0.379572 0.596564" mass="3.18168" diaginertia="0.0189254 0.0180721 0.00757505"/>
                    <joint name="j2" pos="0 0 0" axis="0 0 -1" limited="true" range="-1.57 1.57" damping="0.1"/>
                    <geom type="mesh" contype="0" conaffinity="0" group="1" rgba="1 1 1 1" mesh="link2"/>
<!--                    <geom name="link2_collision" type="mesh" rgba="1 1 1 1" mesh="link2"/>-->
                    <body name="link3" pos="0 -0.45818 0.0005" quat="0.707105 -0.707108 0 0">
                        <inertial pos="0.0148079 -0.0159925 0.127198" quat="0.874546 -0.136758 -0.0611978 0.461217" mass="3.93616" diaginertia="0.0569273 0.0547312 0.00935482"/>
                        <joint name="j3" pos="0 0 0" axis="0 0 -1" limited="true" range="-2.56 2.56" damping="0.05"/>
                        <geom type="mesh" contype="0" conaffinity="0" group="1" rgba="1 1 1 1" mesh="link3"/>
<!--                        <geom name="link3_collision" type="mesh" rgba="1 1 1 1" mesh="link3"/>-->
                        <body name="link4" pos="0.064454 0.0005 -0.00070508" quat="0.707105 0.707108 0 0">
                            <inertial pos="-0.0145884 -0.0117113 -0.0406158" quat="0.00473736 0.651043 0.564294 0.507635" mass="1.58469" diaginertia="0.00499445 0.00482606 0.00267104"/>
                            <joint name="j4" pos="0 0 0" axis="0 0 1" limited="true" range="0.0 3.05" damping="0.05"/>
                            <geom type="mesh" contype="0" conaffinity="0" group="1" rgba="1 1 1 1" mesh="link4"/>
<!--                            <geom name="link4_collision" type="mesh" rgba="1 1 1 1" mesh="link4"/>-->
                            <body name="link5" pos="-0.052254 -0.45668 0.0005" quat="0.707105 -0.707108 0 0">
                                <inertial pos="-0.00209922 0.0288297 0.222845" quat="0.985159 0.138333 -0.00891494 0.101222" mass="1.92688" diaginertia="0.0293358 0.0290794 0.00210656"/>
                                <joint name="j5" pos="0 0 0" axis="0 0 -1" limited="true" range="-3.05 3.05" damping="0.05"/>
                                <geom type="mesh" contype="0" conaffinity="0" group="1" rgba="1 1 1 1" mesh="link5"/>
                                <!-- <geom name="link5_collision" type="mesh" rgba="1 1 1 1" mesh="link5"/> -->
                                <body name="link6" pos="0 -0.005 -1.1713e-05" quat="-2.59734e-06 -2.59735e-06 -0.707108 -0.707105">
                                    <inertial pos="0.038358 -0.00071885 -0.0021112" quat="0.0131349 0.678937 -0.0198942 0.733809" mass="1.7304" diaginertia="0.005268 0.00492614 0.00345065"/>
                                    <joint name="j6" pos="0 0 0" axis="0 0 1" limited="true" range="-3.14 3.14" damping="0.05"/>
                                    <geom type="mesh" contype="0" conaffinity="0" group="1" rgba="1 1 1 1" mesh="link6"/>
                                    <!-- <geom name="link6_collision" type="mesh" rgba="1 1 1 1" mesh="link6"/> -->
                                    <body name="link7" pos="0.076728 -0.1059 0" quat="0.707105 -0.707108 0 0">
                                        <joint name="j7" pos="0 0 0" axis="0 0 -1" limited="true" range="-3.14 3.14" damping="0.001"/>
                                        <inertial pos="0.00068467 1.5999e-05 0.020834" quat="0.000547318 0.708756 -0.000448023 0.705453" mass="0.16696" diaginertia="0.000143911 8.8902e-05 8.75358e-05"/>
                                        <geom type="mesh" contype="0" conaffinity="0" group="1" rgba="1 1 1 1" mesh="link7"/>
                                        <geom name="link7_collision" type="mesh" rgba="1 1 1 1" mesh="link7"/>
                                        <body name="attachment" pos="0 0 0" quat="0 1 0 0">
                                            <site name="attachment_site"/>
                                        </body>
                                    </body>
                                </body>
                            </body>
                        </body>
                    </body>
                </body>
            </body>
        </body>
    </worldbody>
    <actuator>
        <motor name="a1" ctrllimited="true" ctrlrange="-80.0 80.0"  joint="j1"/>
        <motor name="a2" ctrllimited="true" ctrlrange="-80.0 80.0"  joint="j2"/>
        <motor name="a3" ctrllimited="true" ctrlrange="-80.0 80.0"  joint="j3"/>
        <motor name="a4" ctrllimited="true" ctrlrange="-80.0 80.0"  joint="j4"/>
        <motor name="a5" ctrllimited="true" ctrlrange="-80.0 80.0"  joint="j5"/>
        <motor name="a6" ctrllimited="true" ctrlrange="-80.0 80.0"  joint="j6"/>
        <motor name="a7" ctrllimited="true" ctrlrange="-80.0 80.0"  joint="j7"/>
    </actuator>
</mujoco>
