<mujoco>
    <worldbody>
        <body name="beam">
            <joint name="OBJTx" pos="0 0 0" axis="1 0 0" type="slide" limited="false" damping="0.01" />
            <joint name="OBJTy" pos="0 0 0" axis="0 1 0" type="slide" limited="true" range="-0.2 0" damping="0.01" />
            <joint name="OBJTz" pos="0 0 0" axis="0 0 1" type="slide" limited="false" damping="0.01" />
            <joint name="OBJRx" pos="0 0 0" axis="1 0 0" limited="true" damping="0.1" range="0 0.01"/>
            <joint name="OBJRy" pos="0 0 0" axis="0 1 0" limited="true" damping="0.1" range="0 0.01"/>
            <joint name="OBJRz" pos="0 0 0" axis="0 0 1" limited="true" damping="0.1" range="0 0.01"/>

            <geom name="beam" type="box" pos="0.57 0 0.565" size="0.01 0.12 0.015" rgba="0 0.5 0 0.9" friction="0.01 0.1 0.1"/>
            <geom name="beam_handle" type="box" pos="0.53 -0.11 0.565" size="0.04 0.01 0.015" rgba="0 0.5 0 0.9"/>

            <site name="beam_left" pos="0.57 0.12 0.565" size="0.01" rgba="1 1 0 0.5" type="sphere" />
            <site name="beam_right" pos="0.51 -0.11 0.565" size="0.01" rgba="1 0 0 0.5" type="sphere" />
        </body>
    </worldbody>
</mujoco>
